Workbook
Name UPDATE: 'Data Sheet'!$E$1

Sheet Profit & Loss
A1: ='Data Sheet'!B1 -> KNR CONSTRUCTIONS LTD | H1: =UPDATE -> TATA Motors Ltd | M1: SCREENER.IN
A3: Narration | B3: ='Data Sheet'!B16 -> 42825 | C3: ='Data Sheet'!C16 -> 43190 | D3: ='Data Sheet'!D16 -> 43555 | E3: ='Data Sheet'!E16 -> 43921 | F3: ='Data Sheet'!F16 -> 44286 | G3: ='Data Sheet'!G16 -> 44651 | H3: ='Data Sheet'!H16 -> 45016 | I3: ='Data Sheet'!I16 -> 45382 | ... K3: ='Data Sheet'!K16 -> 46112 | L3: Trailing | M3: Best Case | N3: Worst Case
A4: Sales | B4: ='Data Sheet'!B17 -> 1642.13 | C4: ='Data Sheet'!C17 -> 2069.6 | D4: ='Data Sheet'!D17 -> 2291.5 | E4: ='Data Sheet'!E17 -> 2451.68 | F4: ='Data Sheet'!F17 -> 2903.63 | G4: ='Data Sheet'!G17 -> 3605.82 | H4: ='Data Sheet'!H17 -> 4062.36 | I4: ='Data Sheet'!I17 -> 4429.49 | ... K4: ='Data Sheet'!K17 -> 2698.01 | L4: =SUM(#REF!) -> #REF! | M4: =$K4+M23*K4 -> 2353.9574 | N4: =$K4+N23*L4 -> #REF!
A5: Expenses | B5: =SUM('Data Sheet'!B18,'Data Sheet'!B20:B24, -1*'Data Sheet'!B19) -> 1377.67 | C5: =SUM('Data Sheet'!C18,'Data Sheet'!C20:C24, -1*'Data Sheet'!C19) -> 1620.21 | D5: =SUM('Data Sheet'!D18,'Data Sheet'!D20:D24, -1*'Data Sheet'!D19) -> 1753.93 | E5: =SUM('Data Sheet'!E18,'Data Sheet'!E20:E24, -1*'Data Sheet'!E19) -> 1828.69 | F5: =SUM('Data Sheet'!F18,'Data Sheet'!F20:F24, -1*'Data Sheet'!F19) -> 2204.72 | G5: =SUM('Data Sheet'!G18,'Data Sheet'!G20:G24, -1*'Data Sheet'!G19) -> 2804.11 | H5: =SUM('Data Sheet'!H18,'Data Sheet'!H20:H24, -1*'Data Sheet'!H19) -> 3144.68 | I5: =SUM('Data Sheet'!I18,'Data Sheet'!I20:I24, -1*'Data Sheet'!I19) -> 3380.5 | ... K5: =SUM('Data Sheet'!K18,'Data Sheet'!K20:K24, -1*'Data Sheet'!K19) -> 1986.66 | L5: =SUM(#REF!) -> #REF! | M5: =M4-M6 -> #REF! | N5: =N4-N6 -> #REF!
A6: Operating Profit | B6: =B4-B5 -> 264.46 | C6: =C4-C5 -> 449.39 | D6: =D4-D5 -> 537.57 | E6: =E4-E5 -> 622.99 | F6: =F4-F5 -> 698.91 | G6: =G4-G5 -> 801.71 | H6: =H4-H5 -> 917.68 | I6: =I4-I5 -> 1048.99 | ... K6: =K4-K5 -> 711.35 | L6: =SUM(#REF!) -> #REF! | M6: =M4*M24 -> #REF! | N6: =N4*N24 -> #REF!
A7: Other Income | B7: ='Data Sheet'!B25 -> 29.57 | C7: ='Data Sheet'!C25 -> 54.94 | D7: ='Data Sheet'!D25 -> 74.76 | E7: ='Data Sheet'!E25 -> 66.39 | F7: ='Data Sheet'!F25 -> 143.99 | G7: ='Data Sheet'!G25 -> 77.73 | H7: ='Data Sheet'!H25 -> 97.67 | I7: ='Data Sheet'!I25 -> 162.19 | ... K7: ='Data Sheet'!K25 -> 65.22 | L7: =SUM(#REF!) -> #REF! | M7: 0 | N7: 0
A8: Depreciation | B8: ='Data Sheet'!B26 -> 115.63 | C8: ='Data Sheet'!C26 -> 193.6 | D8: ='Data Sheet'!D26 -> 230.13 | E8: ='Data Sheet'!E26 -> 254.13 | F8: ='Data Sheet'!F26 -> 189.9 | G8: ='Data Sheet'!G26 -> 164.92 | H8: ='Data Sheet'!H26 -> 180.7 | I8: ='Data Sheet'!I26 -> 156.83 | ... K8: ='Data Sheet'!K26 -> 59.46 | L8: =SUM(#REF!) -> #REF! | M8: =+$L8 -> #REF! | N8: =+$L8 -> #REF!
A9: Interest | B9: ='Data Sheet'!B27 -> 72.67 | C9: ='Data Sheet'!C27 -> 82.5 | D9: ='Data Sheet'!D27 -> 89.84 | E9: ='Data Sheet'!E27 -> 110.78 | F9: ='Data Sheet'!F27 -> 133.21 | G9: ='Data Sheet'!G27 -> 151.14 | H9: ='Data Sheet'!H27 -> 153.4 | I9: ='Data Sheet'!I27 -> 105.89 | ... K9: ='Data Sheet'!K27 -> 211.73 | L9: =SUM(#REF!) -> #REF! | M9: =+$L9 -> #REF! | N9: =+$L9 -> #REF!
A10: Profit before tax | B10: ='Data Sheet'!B28 -> 105.73 | C10: ='Data Sheet'!C28 -> 228.23 | D10: ='Data Sheet'!D28 -> 292.36 | E10: ='Data Sheet'!E28 -> 324.47 | F10: ='Data Sheet'!F28 -> 519.79 | G10: ='Data Sheet'!G28 -> 563.38 | H10: ='Data Sheet'!H28 -> 681.25 | I10: ='Data Sheet'!I28 -> 948.46 | ... K10: ='Data Sheet'!K28 -> 505.38 | L10: =SUM(#REF!) -> #REF! | M10: =M6+M7-SUM(M8:M9) -> #REF! | N10: =N6+N7-SUM(N8:N9) -> #REF!
A11: Tax | B11: ='Data Sheet'!B29 -> 6.99 | C11: ='Data Sheet'!C29 -> -0.73 | D11: ='Data Sheet'!D29 -> 27.47 | E11: ='Data Sheet'!E29 -> 68.53 | F11: ='Data Sheet'!F29 -> 136.96 | G11: ='Data Sheet'!G29 -> 196.99 | H11: ='Data Sheet'!H29 -> 241.84 | I11: ='Data Sheet'!I29 -> 196.17 | ... K11: ='Data Sheet'!K29 -> 85.95 | L11: =SUM(#REF!) -> #REF! | M11: =IF($L10>0,$L11/$L10,0) -> #REF! | N11: =IF($L10>0,$L11/$L10,0) -> #REF!
A12: Net profit | B12: ='Data Sheet'!B30 -> 114.9 | C12: ='Data Sheet'!C30 -> 243.48 | D12: ='Data Sheet'!D30 -> 270.51 | E12: ='Data Sheet'!E30 -> 265.51 | F12: ='Data Sheet'!F30 -> 407.38 | G12: ='Data Sheet'!G30 -> 381.84 | H12: ='Data Sheet'!H30 -> 458.01 | I12: ='Data Sheet'!I30 -> 777.4 | ... K12: ='Data Sheet'!K30 -> 437.08 | L12: =SUM(#REF!) -> #REF! | M12: =M10-M11*M10 -> #REF! | N12: =N10-N11*N10 -> #REF!
A13: EPS | B13: =IF('Data Sheet'!B93>0,B12/'Data Sheet'!B93,0) -> 4.0860597 | C13: =IF('Data Sheet'!C93>0,C12/'Data Sheet'!C93,0) -> 8.658606 | D13: =IF('Data Sheet'!D93>0,D12/'Data Sheet'!D93,0) -> 9.6198435 | E13: =IF('Data Sheet'!E93>0,E12/'Data Sheet'!E93,0) -> 9.4420341 | F13: =IF('Data Sheet'!F93>0,F12/'Data Sheet'!F93,0) -> 14.487198 | G13: =IF('Data Sheet'!G93>0,G12/'Data Sheet'!G93,0) -> 13.578947 | H13: =IF('Data Sheet'!H93>0,H12/'Data Sheet'!H93,0) -> 16.287696 | I13: =IF('Data Sheet'!I93>0,I12/'Data Sheet'!I93,0) -> 27.645804 | ... K13: =IF('Data Sheet'!K93>0,K12/'Data Sheet'!K93,0) -> 15.543385 | L13: =IF('Data Sheet'!$B6>0,'Profit & Loss'!L12/'Data Sheet'!$B6,0) -> #REF! | M13: =IF('Data Sheet'!$B6>0,'Profit & Loss'!M12/'Data Sheet'!$B6,0) -> #REF! | N13: =IF('Data Sheet'!$B6>0,'Profit & Loss'!N12/'Data Sheet'!$B6,0) -> #REF!
A14: Price to earning | B14: =IF(B15>0,B15/B13,"") -> 23.587516 | C14: =IF(C15>0,C15/C13,"") -> 16.399869 | D14: =IF(D15>0,D15/D13,"") -> 13.584421 | E14: =IF(E15>0,E15/E13,"") -> 10.405597 | F14: =IF(F15>0,F15/F13,"") -> 14.730247 | G14: =IF(G15>0,G15/G13,"") -> 20.925775 | H14: =IF(H15>0,H15/H13,"") -> 15.576175 | I14: =IF(I15>0,I15/I13,"") -> 8.9091279 | ... K14: =IF(K15>0,K15/K13,"") -> 7.2725469 | L14: =IF(L13>0,L15/L13,0) -> #REF! | M14: =M25 -> #REF! | N14: =N25 -> #REF!
A15: Price | B15: ='Data Sheet'!B90 -> 96.38 | C15: ='Data Sheet'!C90 -> 142 | D15: ='Data Sheet'!D90 -> 130.68 | E15: ='Data Sheet'!E90 -> 98.25 | F15: ='Data Sheet'!F90 -> 213.4 | G15: ='Data Sheet'!G90 -> 284.15 | H15: ='Data Sheet'!H90 -> 253.7 | I15: ='Data Sheet'!I90 -> 246.3 | ... K15: ='Data Sheet'!K90 -> 113.04 | L15: ='Data Sheet'!B8 -> 126.7 | M15: =M13*M14 -> #REF! | N15: =N13*N14 -> #REF!
A17: RATIOS:
A18: Dividend Payout | B18: =IF('Data Sheet'!B30>0, 'Data Sheet'!B31/'Data Sheet'!B30, 0) -> 0.061183638 | C18: =IF('Data Sheet'!C30>0, 'Data Sheet'!C31/'Data Sheet'!C30, 0) -> 0.023081978 | D18: =IF('Data Sheet'!D30>0, 'Data Sheet'!D31/'Data Sheet'!D30, 0) -> 0.020775572 | E18: =IF('Data Sheet'!E30>0, 'Data Sheet'!E31/'Data Sheet'!E30, 0) -> 0.026477345 | F18: =IF('Data Sheet'!F30>0, 'Data Sheet'!F31/'Data Sheet'!F30, 0) -> 0.017256615 | G18: =IF('Data Sheet'!G30>0, 'Data Sheet'!G31/'Data Sheet'!G30, 0) -> 0.018410853 | H18: =IF('Data Sheet'!H30>0, 'Data Sheet'!H31/'Data Sheet'!H30, 0) -> 0.01534901 | I18: =IF('Data Sheet'!I30>0, 'Data Sheet'!I31/'Data Sheet'!I30, 0) -> 0.0090429637 | ... K18: =IF('Data Sheet'!K30>0, 'Data Sheet'!K31/'Data Sheet'!K30, 0) -> 0.016084012
A19: OPM | B19: =IF(B6>0,B6/B4,0) -> 0.16104693 | C19: =IF(C6>0,C6/C4,0) -> 0.21713858 | D19: =IF(D6>0,D6/D4,0) -> 0.23459306 | E19: =IF(E6>0,E6/E4,0) -> 0.25410739 | F19: =IF(F6>0,F6/F4,0) -> 0.24070216 | G19: =IF(G6>0,G6/G4,0) -> 0.22233778 | H19: =IF(H6>0,H6/H4,0) -> 0.22589825 | I19: =IF(I6>0,I6/I4,0) -> 0.23681959 | ... L19: =IF(L6>0,L6/L4,0) -> #REF!
G22: TRENDS: | H22: 10 YEARS | I22: 7 YEARS | J22: 5 YEARS | K22: 3 YEARS | L22: RECENT | M22: BEST | N22: WORST
G23: Sales Growth | H23: =IF(B4=0,"",POWER($K4/B4,1/9)-1) -> 0.056719101 | I23: =IF(D4=0,"",POWER($K4/D4,1/7)-1) -> 0.023603957 | J23: =IF(F4=0,"",POWER($K4/F4,1/5)-1) -> -0.014582079 | K23: =IF(H4=0,"",POWER($K4/H4, 1/3)-1) -> -0.12752087 | L23: =IF(ISERROR(MAX(IF(J4=0,"",(K4-J4)/J4),IF(K4=0,"",(L4-K4)/K4))),"",MAX(IF(J4=0,"",(K4-J4)/J4),IF(K4=0,"",(L4-K4)/K4))) | M23: =MAX(K23:L23) -> -0.12752087 | N23: =MIN(H23:L23) -> -0.12752087
G24: OPM | H24: =IF(SUM(B4:$K$4)=0,"",SUMPRODUCT(B19:$K$19,B4:$K$4)/SUM(B4:$K$4)) -> 0.24792388 | I24: =IF(SUM(E4:$K$4)=0,"",SUMPRODUCT(E19:$K$19,E4:$K$4)/SUM(E4:$K$4)) -> 0.25743731 | J24: =IF(SUM(G4:$K$4)=0,"",SUMPRODUCT(G19:$K$19,G4:$K$4)/SUM(G4:$K$4)) -> 0.26034063 | K24: =IF(SUM(I4:$K$4)=0, "", SUMPRODUCT(I19:$K$19,I4:$K$4)/SUM(I4:$K$4)) -> 0.28365151 | L24: =L19 -> #REF! | M24: =MAX(K24:L24) -> #REF! | N24: =MIN(H24:L24) -> #REF!
G25: Price to Earning | H25: =IF(ISERROR(AVERAGEIF(B14:$L14,">0")),"",AVERAGEIF(B14:$L14,">0")) -> 13.779432 | I25: =IF(ISERROR(AVERAGEIF(E14:$L14,">0")),"",AVERAGEIF(E14:$L14,">0")) -> 12.031787 | J25: =IF(ISERROR(AVERAGEIF(G14:$L14,">0")),"",AVERAGEIF(G14:$L14,">0")) -> 11.817333 | K25: =IF(ISERROR(AVERAGEIF(I14:$L14,">0")),"",AVERAGEIF(I14:$L14,">0")) -> 7.5282389 | L25: =L14 -> #REF! | M25: =MAX(K25:L25) -> #REF! | N25: =MIN(H25:L25) -> #REF!

Sheet Financials

Sheet HistoricalFS
B2: ="Historical Financial Statement - "&UPDATE -> Historical Financial Statement - TATA Motors Ltd
B3: Years | C3: ='Data Sheet'!B16 -> 42825 | D3: ='Data Sheet'!C16 -> 43190 | E3: ='Data Sheet'!D16 -> 43555 | F3: ='Data Sheet'!E16 -> 43921 | G3: ='Data Sheet'!F16 -> 44286 | H3: ='Data Sheet'!G16 -> 44651 | I3: ='Data Sheet'!H16 -> 45016 | J3: ='Data Sheet'!I16 -> 45382 | ... L3: ='Data Sheet'!K16 -> 46112 | M3: LTM
A5: # | B5: Income Statement
B6: Sales | C6: =IFERROR('Data Sheet'!B17,0) -> 1642.13 | D6: =IFERROR('Data Sheet'!C17,0) -> 2069.6 | E6: =IFERROR('Data Sheet'!D17,0) -> 2291.5 | F6: =IFERROR('Data Sheet'!E17,0) -> 2451.68 | G6: =IFERROR('Data Sheet'!F17,0) -> 2903.63 | H6: =IFERROR('Data Sheet'!G17,0) -> 3605.82 | I6: =IFERROR('Data Sheet'!H17,0) -> 4062.36 | J6: =IFERROR('Data Sheet'!I17,0) -> 4429.49 | ... L6: =IFERROR('Data Sheet'!K17,0) -> 2698.01 | M6: =IFERROR(SUM('Data Sheet'!H42:K42),0) -> 2698.01
B7: Sales Growth | C7: - | D7: =D6/C6-1 -> 0.26031435 | E7: =E6/D6-1 -> 0.10721879 | F7: =F6/E6-1 -> 0.069901811 | G7: =G6/F6-1 -> 0.18434298 | H7: =H6/G6-1 -> 0.24183178 | I7: =I6/H6-1 -> 0.12661198 | J7: =J6/I6-1 -> 0.090373576 | K7: =K6/J6-1 -> 0.073073875 | ... M7: =M6/L6-1 -> 0
B9: COGS | C9: =IFERROR(SUM('Data Sheet'!B18,'Data Sheet'!B20:B22)-1*'Data Sheet'!B19,0) -> 1310.17 | D9: =IFERROR(SUM('Data Sheet'!C18,'Data Sheet'!C20:C22)-1*'Data Sheet'!C19,0) -> 1566.03 | E9: =IFERROR(SUM('Data Sheet'!D18,'Data Sheet'!D20:D22)-1*'Data Sheet'!D19,0) -> 1712.61 | F9: =IFERROR(SUM('Data Sheet'!E18,'Data Sheet'!E20:E22)-1*'Data Sheet'!E19,0) -> 1772.46 | G9: =IFERROR(SUM('Data Sheet'!F18,'Data Sheet'!F20:F22)-1*'Data Sheet'!F19,0) -> 2132.95 | H9: =IFERROR(SUM('Data Sheet'!G18,'Data Sheet'!G20:G22)-1*'Data Sheet'!G19,0) -> 2604.25 | I9: =IFERROR(SUM('Data Sheet'!H18,'Data Sheet'!H20:H22)-1*'Data Sheet'!H19,0) -> 3052.17 | J9: =IFERROR(SUM('Data Sheet'!I18,'Data Sheet'!I20:I22)-1*'Data Sheet'!I19,0) -> 3275.34 | ... L9: =IFERROR(SUM('Data Sheet'!K18,'Data Sheet'!K20:K22)-1*'Data Sheet'!K19,0) -> 922.36 | M9: =IFERROR(SUM('Data Sheet'!H43:K43),0) -> 1986.66
B10: COGS % Sales | C10: =C9/C6 -> 0.79784792 | D10: =D9/D6 -> 0.75668245 | E10: =E9/E6 -> 0.74737508 | F10: =F9/F6 -> 0.72295732 | G10: =G9/G6 -> 0.73458051 | H10: =H9/H6 -> 0.72223516 | I10: =I9/I6 -> 0.75132928 | J10: =J9/J6 -> 0.73943953 | ... M10: =M9/M6 -> 0.73634271
B12: Gross Profit | C12: =C6-C9 -> 331.96 | D12: =D6-D9 -> 503.57 | E12: =E6-E9 -> 578.89 | F12: =F6-F9 -> 679.22 | G12: =G6-G9 -> 770.68 | H12: =H6-H9 -> 1001.57 | I12: =I6-I9 -> 1010.19 | J12: =J6-J9 -> 1154.15 | ... M12: =M6-M9 -> 711.35
B13: Gross Margin | C13: =C12/C6 -> 0.20215208 | D13: =D12/D6 -> 0.24331755 | E13: =E12/E6 -> 0.25262492 | F13: =F12/F6 -> 0.27704268 | G13: =G12/G6 -> 0.26541949 | H13: =H12/H6 -> 0.27776484 | I13: =I12/I6 -> 0.24867072 | J13: =J12/J6 -> 0.26056047 | ... M13: =M12/M6 -> 0.26365729
B15: Selling & Gen Exp | C15: =IFERROR(SUM('Data Sheet'!B23:B24),0) -> 67.5 | D15: =IFERROR(SUM('Data Sheet'!C23:C24),0) -> 54.18 | E15: =IFERROR(SUM('Data Sheet'!D23:D24),0) -> 41.32 | F15: =IFERROR(SUM('Data Sheet'!E23:E24),0) -> 56.23 | G15: =IFERROR(SUM('Data Sheet'!F23:F24),0) -> 71.77 | H15: =IFERROR(SUM('Data Sheet'!G23:G24),0) -> 199.86 | I15: =IFERROR(SUM('Data Sheet'!H23:H24),0) -> 92.51 | J15: =IFERROR(SUM('Data Sheet'!I23:I24),0) -> 105.16 | ... L15: =IFERROR(SUM('Data Sheet'!K23:K24),0) -> 1064.3 | M15: 0
B16: S&G Exp % Sales | C16: =C15/C6 -> 0.04110515 | D16: =D15/D6 -> 0.026178972 | E16: =E15/E6 -> 0.018031857 | F16: =F15/F6 -> 0.022935293 | G16: =G15/G6 -> 0.024717337 | H16: =H15/H6 -> 0.05542706 | I16: =I15/I6 -> 0.022772477 | J16: =J15/J6 -> 0.023740882 | ... L16: =L15/L6 -> 0.39447593 | M16: 0
B18: EBITDA | C18: =C12-C15 -> 264.46 | D18: =D12-D15 -> 449.39 | E18: =E12-E15 -> 537.57 | F18: =F12-F15 -> 622.99 | G18: =G12-G15 -> 698.91 | H18: =H12-H15 -> 801.71 | I18: =I12-I15 -> 917.68 | J18: =J12-J15 -> 1048.99 | ... M18: =M12-M15 -> 711.35
B19: EBITDA Margins | C19: =C18/C6 -> 0.16104693 | D19: =D18/D6 -> 0.21713858 | E19: =E18/E6 -> 0.23459306 | F19: =F18/F6 -> 0.25410739 | G19: =G18/G6 -> 0.24070216 | H19: =H18/H6 -> 0.22233778 | I19: =I18/I6 -> 0.22589825 | J19: =J18/J6 -> 0.23681959 | ... M19: =M18/M6 -> 0.26365729
B23: Interest | C23: =IFERROR('Data Sheet'!B27,0) -> 72.67 | D23: =IFERROR('Data Sheet'!C27,0) -> 82.5 | E23: =IFERROR('Data Sheet'!D27,0) -> 89.84 | F23: =IFERROR('Data Sheet'!E27,0) -> 110.78 | G23: =IFERROR('Data Sheet'!F27,0) -> 133.21 | H23: =IFERROR('Data Sheet'!G27,0) -> 151.14 | I23: =IFERROR('Data Sheet'!H27,0) -> 153.4 | J23: =IFERROR('Data Sheet'!I27,0) -> 105.89 | ... L23: =IFERROR('Data Sheet'!K27,0) -> 211.73 | M23: =IFERROR(SUM('Data Sheet'!H46:K46),0) -> 211.73
B24: Interest % Sales | C24: =C23/C6 -> 0.0442535 | D24: =D23/D6 -> 0.039862775 | E24: =E23/E6 -> 0.03920576 | F24: =F23/F6 -> 0.045185342 | G24: =G23/G6 -> 0.045877057 | H24: =H23/H6 -> 0.04191557 | I24: =I23/I6 -> 0.037761301 | J24: =J23/J6 -> 0.023905687 | ... M24: =M23/M6 -> 0.078476359
P25: Other Income | Q25: =IFERROR('Data Sheet'!B25,0) -> 29.57 | R25: =IFERROR('Data Sheet'!C25,0) -> 54.94 | S25: =IFERROR('Data Sheet'!D25,0) -> 74.76 | T25: =IFERROR('Data Sheet'!E25,0) -> 66.39 | U25: =IFERROR('Data Sheet'!F25,0) -> 143.99 | V25: =IFERROR('Data Sheet'!G25,0) -> 77.73 | W25: =IFERROR('Data Sheet'!H25,0) -> 97.67 | X25: =IFERROR('Data Sheet'!I25,0) -> 162.19 | ... Z25: =IFERROR('Data Sheet'!K25,0) -> 65.22 | AA25: =IFERROR(SUM('Data Sheet'!H44:K44),0) -> 65.23
B26: Depreciation | C26: =IFERROR('Data Sheet'!B26,0) -> 115.63 | D26: =IFERROR('Data Sheet'!C26,0) -> 193.6 | E26: =IFERROR('Data Sheet'!D26,0) -> 230.13 | F26: =IFERROR('Data Sheet'!E26,0) -> 254.13 | G26: =IFERROR('Data Sheet'!F26,0) -> 189.9 | H26: =IFERROR('Data Sheet'!G26,0) -> 164.92 | I26: =IFERROR('Data Sheet'!H26,0) -> 180.7 | J26: =IFERROR('Data Sheet'!I26,0) -> 156.83 | ... L26: =IFERROR('Data Sheet'!K26,0) -> 59.46 | M26: 0
B27: Depreciation % Sales | C27: =C26/C6 -> 0.070414644 | D27: =D26/D6 -> 0.093544646 | E27: =E26/E6 -> 0.10042767 | F27: =F26/F6 -> 0.10365545 | G27: =G26/G6 -> 0.065400895 | H27: =H26/H6 -> 0.045737169 | I27: =I26/I6 -> 0.044481533 | J27: =J26/J6 -> 0.035405882 | ... M27: =M26/M6 -> 0
B29: EBIT | C29: =C18-C26 -> 148.83 | D29: =D18-D26 -> 255.79 | E29: =E18-E26 -> 307.44 | F29: =F18-F26 -> 368.86 | G29: =G18-G26 -> 509.01 | H29: =H18-H26 -> 636.79 | I29: =I18-I26 -> 736.98 | J29: =J18-J26 -> 892.16 | ... M29: =M18-M26 -> 711.35
B30: EBIT % Sales | C30: =C29/C6 -> 0.090632289 | D30: =D29/D6 -> 0.12359393 | E30: =E29/E6 -> 0.13416539 | F30: =F29/F6 -> 0.15045193 | G30: =G29/G6 -> 0.17530126 | H30: =H29/H6 -> 0.17660061 | I30: =I29/I6 -> 0.18141671 | J30: =J29/J6 -> 0.20141371 | ... M30: =M29/M6 -> 0.26365729
B32: Earnings Before Tax | C32: =C18-C23-C26 -> 76.16 | D32: =D18-D23-D26 -> 173.29 | E32: =E18-E23-E26 -> 217.6 | F32: =F18-F23-F26 -> 258.08 | G32: =G18-G23-G26 -> 375.8 | H32: =H18-H23-H26 -> 485.65 | I32: =I18-I23-I26 -> 583.58 | J32: =J18-J23-J26 -> 786.27 | ... M32: =M18-M23-M26 -> 499.62
B33: EBT % Sales | C33: =C32/C6 -> 0.046378789 | D33: =D32/D6 -> 0.083731156 | E33: =E32/E6 -> 0.094959633 | F33: =F32/F6 -> 0.10526659 | G33: =G32/G6 -> 0.1294242 | H33: =H32/H6 -> 0.13468504 | I33: =I32/I6 -> 0.14365541 | J33: =J32/J6 -> 0.17750802 | ... M33: =M32/M6 -> 0.18518093
B35: Tax | C35: =IFERROR('Data Sheet'!B29,0) -> 6.99 | D35: =IFERROR('Data Sheet'!C29,0) -> -0.73 | E35: =IFERROR('Data Sheet'!D29,0) -> 27.47 | F35: =IFERROR('Data Sheet'!E29,0) -> 68.53 | G35: =IFERROR('Data Sheet'!F29,0) -> 136.96 | H35: =IFERROR('Data Sheet'!G29,0) -> 196.99 | I35: =IFERROR('Data Sheet'!H29,0) -> 241.84 | J35: =IFERROR('Data Sheet'!I29,0) -> 196.17 | ... L35: =IFERROR('Data Sheet'!K29,0) -> 85.95 | M35: =IFERROR(SUM('Data Sheet'!H48:K48),0) -> 85.94
B36: Effective Tax Rate | C36: =C35/C32 -> 0.091780462 | D36: =D35/D32 -> -0.0042125916 | E36: =E35/E32 -> 0.12624081 | F36: =F35/F32 -> 0.26553782 | G36: =G35/G32 -> 0.36444918 | H36: =H35/H32 -> 0.40562133 | I36: =I35/I32 -> 0.41440762 | J36: =J35/J32 -> 0.24949445 | ... M36: =M35/M32 -> 0.17201073
B38: Net Profit | C38: =C32-C35 -> 69.17 | D38: =D32-D35 -> 174.02 | E38: =E32-E35 -> 190.13 | F38: =F32-F35 -> 189.55 | G38: =G32-G35 -> 238.84 | H38: =H32-H35 -> 288.66 | I38: =I32-I35 -> 341.74 | J38: =J32-J35 -> 590.1 | ... M38: =M32-M35 -> 413.68
B39: Net Margin | C39: =C38/C6 -> 0.042122122 | D39: =D38/D6 -> 0.084083881 | E39: =E38/E6 -> 0.082971852 | F39: =F38/F6 -> 0.077314331 | G39: =G38/G6 -> 0.082255659 | H39: =H38/H6 -> 0.080053913 | I39: =I38/I6 -> 0.084123514 | J39: =J38/J6 -> 0.13322075 | ... M39: =M38/M6 -> 0.15332782
B41: No. of Equity Shares | C41: =IFERROR('Data Sheet'!B93,0) -> 28.12 | D41: =IFERROR('Data Sheet'!C93,0) -> 28.12 | E41: =IFERROR('Data Sheet'!D93,0) -> 28.12 | F41: =IFERROR('Data Sheet'!E93,0) -> 28.12 | G41: =IFERROR('Data Sheet'!F93,0) -> 28.12 | H41: =IFERROR('Data Sheet'!G93,0) -> 28.12 | I41: =IFERROR('Data Sheet'!H93,0) -> 28.12 | J41: =IFERROR('Data Sheet'!I93,0) -> 28.12 | ... L41: =IFERROR('Data Sheet'!K93,0) -> 28.12 | M41: =IFERROR('Data Sheet'!K93,0) -> 28.12
B43: EPS | C43: =IFERROR(C38/C41,0) -> 2.4598151 | D43: =IFERROR(D38/D41,0) -> 6.188478 | E43: =IFERROR(E38/E41,0) -> 6.7613798 | F43: =IFERROR(F38/F41,0) -> 6.7407539 | G43: =IFERROR(G38/G41,0) -> 8.4935989 | H43: =IFERROR(H38/H41,0) -> 10.265292 | I43: =IFERROR(I38/I41,0) -> 12.152916 | J43: =IFERROR(J38/J41,0) -> 20.985064 | ... M43: =IFERROR(M38/M41,0) -> 14.711238
B44: EPS Growth % | D44: =IFERROR(D43/C43-1,0) -> 1.5158306 | E44: =IFERROR(E43/D43-1,0) -> 0.092575566 | F44: =IFERROR(F43/E43-1,0) -> -0.0030505444 | G44: =IFERROR(G43/F43-1,0) -> 0.26003693 | H44: =IFERROR(H43/G43-1,0) -> 0.20859153 | I44: =IFERROR(I43/H43-1,0) -> 0.18388415 | J44: =IFERROR(J43/I43-1,0) -> 0.72675133 | K44: =IFERROR(K43/J43-1,0) -> 0.40601593 | ... M44: =IFERROR(M43/L43-1,0) -> 0.16789475
B46: Divident per share | C46: =-IFERROR('Data Sheet'!B31/C41,0) -> -0.25 | D46: =-IFERROR('Data Sheet'!C31/D41,0) -> -0.19985775 | E46: =-IFERROR('Data Sheet'!D31/E41,0) -> -0.19985775 | F46: =-IFERROR('Data Sheet'!E31/F41,0) -> -0.25 | G46: =-IFERROR('Data Sheet'!F31/G41,0) -> -0.25 | H46: =-IFERROR('Data Sheet'!G31/H41,0) -> -0.25 | I46: =-IFERROR('Data Sheet'!H31/I41,0) -> -0.25 | J46: =-IFERROR('Data Sheet'!I31/J41,0) -> -0.25 | ... M46: =-IFERROR('Data Sheet'!L31/M41,0) -> 0
B47: Dividend Payout ratio | C47: =IFERROR(C46/C43,0) -> -0.10163366 | D47: =IFERROR(D46/D43,0) -> -0.032295138 | E47: =IFERROR(E46/E43,0) -> -0.029558723 | F47: =IFERROR(F46/F43,0) -> -0.03708784 | G47: =IFERROR(G46/G43,0) -> -0.029433931 | H47: =IFERROR(H46/H43,0) -> -0.024353911 | I47: =IFERROR(I46/I43,0) -> -0.020571194 | J47: =IFERROR(J46/J43,0) -> -0.011913235 | ... M47: =IFERROR(M46/M43,0) -> 0
B49: Retained Earnings | C49: =IFERROR(IF(C43>C46,1-C47,0),0) -> 1.1016337 | D49: =IFERROR(IF(D43>D46,1-D47,0),0) -> 1.0322951 | E49: =IFERROR(IF(E43>E46,1-E47,0),0) -> 1.0295587 | F49: =IFERROR(IF(F43>F46,1-F47,0),0) -> 1.0370878 | G49: =IFERROR(IF(G43>G46,1-G47,0),0) -> 1.0294339 | H49: =IFERROR(IF(H43>H46,1-H47,0),0) -> 1.0243539 | I49: =IFERROR(IF(I43>I46,1-I47,0),0) -> 1.0205712 | J49: =IFERROR(IF(J43>J46,1-J47,0),0) -> 1.0119132 | ... M49: =IFERROR(IF(M43>M46,1-M47,0),0) -> 1
A51: # | B51: Balance sheet
B53: Equity Share Capital | C53: =IFERROR('Data Sheet'!B57,0) -> 28.12 | D53: =IFERROR('Data Sheet'!C57,0) -> 28.12 | E53: =IFERROR('Data Sheet'!D57,0) -> 28.12 | F53: =IFERROR('Data Sheet'!E57,0) -> 28.12 | G53: =IFERROR('Data Sheet'!F57,0) -> 56.25 | H53: =IFERROR('Data Sheet'!G57,0) -> 56.25 | I53: =IFERROR('Data Sheet'!H57,0) -> 56.25 | J53: =IFERROR('Data Sheet'!I57,0) -> 56.25 | ... L53: =IFERROR('Data Sheet'!K57,0) -> 56.25
B54: Reserves | C54: =IFERROR('Data Sheet'!B58,0) -> 785.8 | D54: =IFERROR('Data Sheet'!C58,0) -> 1019.64 | E54: =IFERROR('Data Sheet'!D58,0) -> 1282.7 | F54: =IFERROR('Data Sheet'!E58,0) -> 1532.54 | G54: =IFERROR('Data Sheet'!F58,0) -> 1911.57 | H54: =IFERROR('Data Sheet'!G58,0) -> 2271.46 | I54: =IFERROR('Data Sheet'!H58,0) -> 2722.95 | J54: =IFERROR('Data Sheet'!I58,0) -> 3497.9 | ... L54: =IFERROR('Data Sheet'!K58,0) -> 4915.74
B55: Borrowings | C55: =IFERROR('Data Sheet'!B59,0) -> 721.14 | D55: =IFERROR('Data Sheet'!C59,0) -> 770.4 | E55: =IFERROR('Data Sheet'!D59,0) -> 758.21 | F55: =IFERROR('Data Sheet'!E59,0) -> 874.54 | G55: =IFERROR('Data Sheet'!F59,0) -> 764.37 | H55: =IFERROR('Data Sheet'!G59,0) -> 1463.54 | I55: =IFERROR('Data Sheet'!H59,0) -> 652.06 | J55: =IFERROR('Data Sheet'!I59,0) -> 1262.44 | ... L55: =IFERROR('Data Sheet'!K59,0) -> 2444.25
B56: Other Liabilities | C56: =IFERROR('Data Sheet'!B60,0) -> 707.13 | D56: =IFERROR('Data Sheet'!C60,0) -> 789.82 | E56: =IFERROR('Data Sheet'!D60,0) -> 660.03 | F56: =IFERROR('Data Sheet'!E60,0) -> 1068.14 | G56: =IFERROR('Data Sheet'!F60,0) -> 1274.99 | H56: =IFERROR('Data Sheet'!G60,0) -> 1479.08 | I56: =IFERROR('Data Sheet'!H60,0) -> 910.75 | J56: =IFERROR('Data Sheet'!I60,0) -> 987.2 | ... L56: =IFERROR('Data Sheet'!K60,0) -> 705.31
B57: Total Liabilities | C57: =IFERROR('Data Sheet'!B61,0) -> 2242.19 | D57: =IFERROR('Data Sheet'!C61,0) -> 2607.98 | E57: =IFERROR('Data Sheet'!D61,0) -> 2729.06 | F57: =IFERROR('Data Sheet'!E61,0) -> 3503.34 | G57: =IFERROR('Data Sheet'!F61,0) -> 4007.18 | H57: =IFERROR('Data Sheet'!G61,0) -> 5270.33 | I57: =IFERROR('Data Sheet'!H61,0) -> 4342.01 | J57: =IFERROR('Data Sheet'!I61,0) -> 5803.79 | ... L57: =IFERROR('Data Sheet'!K61,0) -> 8121.55
B59: Fixed Assets Net Block | C59: =IFERROR('Data Sheet'!B62,0) -> 1228.44 | D59: =IFERROR('Data Sheet'!C62,0) -> 1341.35 | E59: =IFERROR('Data Sheet'!D62,0) -> 1320.52 | F59: =IFERROR('Data Sheet'!E62,0) -> 1274.82 | G59: =IFERROR('Data Sheet'!F62,0) -> 776 | H59: =IFERROR('Data Sheet'!G62,0) -> 889.9 | I59: =IFERROR('Data Sheet'!H62,0) -> 890.49 | J59: =IFERROR('Data Sheet'!I62,0) -> 806.36 | ... L59: =IFERROR('Data Sheet'!K62,0) -> 428.92
B60: Capital Work in Progress | C60: =IFERROR('Data Sheet'!B63,0) -> 91.26 | D60: =IFERROR('Data Sheet'!C63,0) -> 1.15 | E60: =IFERROR('Data Sheet'!D63,0) -> 0.01 | F60: =IFERROR('Data Sheet'!E63,0) -> 10.15 | G60: =IFERROR('Data Sheet'!F63,0) -> 2.38 | H60: =IFERROR('Data Sheet'!G63,0) -> 20.62 | I60: =IFERROR('Data Sheet'!H63,0) -> 2.51 | J60: =IFERROR('Data Sheet'!I63,0) -> 2.18 | ... L60: =IFERROR('Data Sheet'!K63,0) -> 0.12
...

Sheet Ratio Analysis
B2: ="Ratio Analysis - "&UPDATE -> Ratio Analysis - TATA Motors Ltd
B3: Years | C3: ='Data Sheet'!B16 -> 42825 | D3: ='Data Sheet'!C16 -> 43190 | E3: ='Data Sheet'!D16 -> 43555 | F3: ='Data Sheet'!E16 -> 43921 | G3: ='Data Sheet'!F16 -> 44286 | H3: ='Data Sheet'!G16 -> 44651 | I3: ='Data Sheet'!H16 -> 45016 | J3: ='Data Sheet'!I16 -> 45382 | ... L3: ='Data Sheet'!K16 -> 46112 | M3: Trend | N3: Mean | O3: Median
B5: SalesGrowth | D5: =IFERROR(HistoricalFS!D7,0) -> 0.26031435 | E5: =IFERROR(HistoricalFS!E7,0) -> 0.10721879 | F5: =IFERROR(HistoricalFS!F7,0) -> 0.069901811 | G5: =IFERROR(HistoricalFS!G7,0) -> 0.18434298 | H5: =IFERROR(HistoricalFS!H7,0) -> 0.24183178 | I5: =IFERROR(HistoricalFS!I7,0) -> 0.12661198 | J5: =IFERROR(HistoricalFS!J7,0) -> 0.090373576 | K5: =IFERROR(HistoricalFS!K7,0) -> 0.073073875 | L5: =IFERROR(HistoricalFS!L7,0) -> -0.43237671 | N5: =IFERROR(AVERAGE(D5:L5),0) -> 0.080143602 | O5: =IFERROR(MEDIAN(C5:L5),0) -> 0.10721879
B6: EBITDA Growth | D6: =IFERROR(HistoricalFS!D18/HistoricalFS!C18-1,0) -> 0.69927399 | E6: =IFERROR(HistoricalFS!E18/HistoricalFS!D18-1,0) -> 0.19622154 | F6: =IFERROR(HistoricalFS!F18/HistoricalFS!E18-1,0) -> 0.15890024 | G6: =IFERROR(HistoricalFS!G18/HistoricalFS!F18-1,0) -> 0.12186391 | H6: =IFERROR(HistoricalFS!H18/HistoricalFS!G18-1,0) -> 0.14708618 | I6: =IFERROR(HistoricalFS!I18/HistoricalFS!H18-1,0) -> 0.1446533 | J6: =IFERROR(HistoricalFS!J18/HistoricalFS!I18-1,0) -> 0.14308909 | K6: =IFERROR(HistoricalFS!K18/HistoricalFS!J18-1,0) -> 0.53445695 | L6: =IFERROR(HistoricalFS!L18/HistoricalFS!K18-1,0) -> -0.55806614 | N6: =IFERROR(AVERAGE(D6:L6),0) -> 0.17638656 | O6: =IFERROR(MEDIAN(C6:L6),0) -> 0.14708618
B7: EBIT Growth | D7: =IFERROR(HistoricalFS!D32/HistoricalFS!C32-1,0) -> 1.2753414 | E7: =IFERROR(HistoricalFS!E32/HistoricalFS!D32-1,0) -> 0.25569854 | F7: =IFERROR(HistoricalFS!F32/HistoricalFS!E32-1,0) -> 0.18602941 | G7: =IFERROR(HistoricalFS!G32/HistoricalFS!F32-1,0) -> 0.45613763 | H7: =IFERROR(HistoricalFS!H32/HistoricalFS!G32-1,0) -> 0.29230974 | I7: =IFERROR(HistoricalFS!I32/HistoricalFS!H32-1,0) -> 0.20164728 | J7: =IFERROR(HistoricalFS!J32/HistoricalFS!I32-1,0) -> 0.3473217 | K7: =IFERROR(HistoricalFS!K32/HistoricalFS!J32-1,0) -> 0.38298549 | L7: =IFERROR(HistoricalFS!L32/HistoricalFS!K32-1,0) -> -0.59521795 | N7: =IFERROR(AVERAGE(D7:L7),0) -> 0.31136147 | O7: =IFERROR(MEDIAN(C7:L7),0) -> 0.29230974
B8: NetProfit Growth | D8: =IFERROR(HistoricalFS!D38/HistoricalFS!C38-1,0) -> 1.5158306 | E8: =IFERROR(HistoricalFS!E38/HistoricalFS!D38-1,0) -> 0.092575566 | F8: =IFERROR(HistoricalFS!F38/HistoricalFS!E38-1,0) -> -0.0030505444 | G8: =IFERROR(HistoricalFS!G38/HistoricalFS!F38-1,0) -> 0.26003693 | H8: =IFERROR(HistoricalFS!H38/HistoricalFS!G38-1,0) -> 0.20859153 | I8: =IFERROR(HistoricalFS!I38/HistoricalFS!H38-1,0) -> 0.18388415 | J8: =IFERROR(HistoricalFS!J38/HistoricalFS!I38-1,0) -> 0.72675133 | K8: =IFERROR(HistoricalFS!K38/HistoricalFS!J38-1,0) -> 0.40601593 | L8: =IFERROR(HistoricalFS!L38/HistoricalFS!K38-1,0) -> -0.57308151 | N8: =IFERROR(AVERAGE(D8:L8),0) -> 0.31306155 | O8: =IFERROR(MEDIAN(C8:L8),0) -> 0.20859153
B9: Dividend Growth | D9: =IFERROR(HistoricalFS!D46/HistoricalFS!C46-1,0) -> -0.20056899 | E9: =IFERROR(HistoricalFS!E46/HistoricalFS!D46-1,0) -> 0 | F9: =IFERROR(HistoricalFS!F46/HistoricalFS!E46-1,0) -> 0.25088968 | G9: =IFERROR(HistoricalFS!G46/HistoricalFS!F46-1,0) -> 0 | H9: =IFERROR(HistoricalFS!H46/HistoricalFS!G46-1,0) -> 0 | I9: =IFERROR(HistoricalFS!I46/HistoricalFS!H46-1,0) -> 0 | J9: =IFERROR(HistoricalFS!J46/HistoricalFS!I46-1,0) -> 0 | K9: =IFERROR(HistoricalFS!K46/HistoricalFS!J46-1,0) -> 0 | L9: =IFERROR(HistoricalFS!L46/HistoricalFS!K46-1,0) -> 0 | N9: =IFERROR(AVERAGE(D9:L9),0) -> 0.0055911877 | O9: =IFERROR(MEDIAN(C9:L9),0) -> 0
B11: Gross Margin | C11: =IFERROR(HistoricalFS!C13,0) -> 0.20215208 | D11: =IFERROR(HistoricalFS!D13,0) -> 0.24331755 | E11: =IFERROR(HistoricalFS!E13,0) -> 0.25262492 | F11: =IFERROR(HistoricalFS!F13,0) -> 0.27704268 | G11: =IFERROR(HistoricalFS!G13,0) -> 0.26541949 | H11: =IFERROR(HistoricalFS!H13,0) -> 0.27776484 | I11: =IFERROR(HistoricalFS!I13,0) -> 0.24867072 | J11: =IFERROR(HistoricalFS!J13,0) -> 0.26056047 | ... L11: =IFERROR(HistoricalFS!L13,0) -> 0.65813322 | N11: =IFERROR(AVERAGE(C11:L11),0) -> 0.30481262 | O11: =IFERROR(AVERAGE(D11:M11),0) -> 0.31621935
B12: EBITDA Margin | C12: =IFERROR(HistoricalFS!C19,0) -> 0.16104693 | D12: =IFERROR(HistoricalFS!D19,0) -> 0.21713858 | E12: =IFERROR(HistoricalFS!E19,0) -> 0.23459306 | F12: =IFERROR(HistoricalFS!F19,0) -> 0.25410739 | G12: =IFERROR(HistoricalFS!G19,0) -> 0.24070216 | H12: =IFERROR(HistoricalFS!H19,0) -> 0.22233778 | I12: =IFERROR(HistoricalFS!I19,0) -> 0.22589825 | J12: =IFERROR(HistoricalFS!J19,0) -> 0.23681959 | ... L12: =IFERROR(HistoricalFS!L19,0) -> 0.26365729 | N12: =IFERROR(AVERAGE(C12:L12),0) -> 0.23949445 | O12: =IFERROR(AVERAGE(D12:M12),0) -> 0.24821084
B13: EBIT Margin | C13: =IFERROR((HistoricalFS!C18-HistoricalFS!C26)/HistoricalFS!C6,0) -> 0.090632289 | D13: =IFERROR((HistoricalFS!D18-HistoricalFS!D26)/HistoricalFS!D6,0) -> 0.12359393 | E13: =IFERROR((HistoricalFS!E18-HistoricalFS!E26)/HistoricalFS!E6,0) -> 0.13416539 | F13: =IFERROR((HistoricalFS!F18-HistoricalFS!F26)/HistoricalFS!F6,0) -> 0.15045193 | G13: =IFERROR((HistoricalFS!G18-HistoricalFS!G26)/HistoricalFS!G6,0) -> 0.17530126 | H13: =IFERROR((HistoricalFS!H18-HistoricalFS!H26)/HistoricalFS!H6,0) -> 0.17660061 | I13: =IFERROR((HistoricalFS!I18-HistoricalFS!I26)/HistoricalFS!I6,0) -> 0.18141671 | J13: =IFERROR((HistoricalFS!J18-HistoricalFS!J26)/HistoricalFS!J6,0) -> 0.20141371 | ... L13: =IFERROR((HistoricalFS!L18-HistoricalFS!L26)/HistoricalFS!L6,0) -> 0.24161882 | N13: =IFERROR(AVERAGE(C13:L13),0) -> 0.17477307 | O13: =IFERROR(AVERAGE(D13:M13),0) -> 0.18412204
B14: EBT Margin | C14: =IFERROR(HistoricalFS!C33,0) -> 0.046378789 | D14: =IFERROR(HistoricalFS!D33,0) -> 0.083731156 | E14: =IFERROR(HistoricalFS!E33,0) -> 0.094959633 | F14: =IFERROR(HistoricalFS!F33,0) -> 0.10526659 | G14: =IFERROR(HistoricalFS!G33,0) -> 0.1294242 | H14: =IFERROR(HistoricalFS!H33,0) -> 0.13468504 | I14: =IFERROR(HistoricalFS!I33,0) -> 0.14365541 | J14: =IFERROR(HistoricalFS!J33,0) -> 0.17750802 | ... L14: =IFERROR(HistoricalFS!L33,0) -> 0.16314246 | N14: =IFERROR(AVERAGE(C14:L14),0) -> 0.13075249 | O14: =IFERROR(AVERAGE(D14:M14),0) -> 0.14012735
B15: Net Profit Margin | C15: =IFERROR(HistoricalFS!C39,0) -> 0.042122122 | D15: =IFERROR(HistoricalFS!D39,0) -> 0.084083881 | E15: =IFERROR(HistoricalFS!E39,0) -> 0.082971852 | F15: =IFERROR(HistoricalFS!F39,0) -> 0.077314331 | G15: =IFERROR(HistoricalFS!G39,0) -> 0.082255659 | H15: =IFERROR(HistoricalFS!H39,0) -> 0.080053913 | I15: =IFERROR(HistoricalFS!I39,0) -> 0.084123514 | J15: =IFERROR(HistoricalFS!J39,0) -> 0.13322075 | ... L15: =IFERROR(HistoricalFS!L39,0) -> 0.13128565 | N15: =IFERROR(AVERAGE(C15:L15),0) -> 0.097198677 | O15: =IFERROR(AVERAGE(D15:M15),0) -> 0.10331829
B17: SalesExp% Sales | C17: =IFERROR(HistoricalFS!C16,0) -> 0.04110515 | D17: =IFERROR(HistoricalFS!D16,0) -> 0.026178972 | E17: =IFERROR(HistoricalFS!E16,0) -> 0.018031857 | F17: =IFERROR(HistoricalFS!F16,0) -> 0.022935293 | G17: =IFERROR(HistoricalFS!G16,0) -> 0.024717337 | H17: =IFERROR(HistoricalFS!H16,0) -> 0.05542706 | I17: =IFERROR(HistoricalFS!I16,0) -> 0.022772477 | J17: =IFERROR(HistoricalFS!J16,0) -> 0.023740882 | ... L17: =IFERROR(HistoricalFS!L16,0) -> 0.39447593 | N17: =IFERROR(AVERAGE(C17:L17),0) -> 0.065318171 | O17: =IFERROR(AVERAGE(D17:M17),0) -> 0.068008506
B18: Deprn%Sales | C18: =IFERROR(HistoricalFS!C27,0) -> 0.070414644 | D18: =IFERROR(HistoricalFS!D27,0) -> 0.093544646 | E18: =IFERROR(HistoricalFS!E27,0) -> 0.10042767 | F18: =IFERROR(HistoricalFS!F27,0) -> 0.10365545 | G18: =IFERROR(HistoricalFS!G27,0) -> 0.065400895 | H18: =IFERROR(HistoricalFS!H27,0) -> 0.045737169 | I18: =IFERROR(HistoricalFS!I27,0) -> 0.044481533 | J18: =IFERROR(HistoricalFS!J27,0) -> 0.035405882 | ... L18: =IFERROR(HistoricalFS!L27,0) -> 0.022038465 | N18: =IFERROR(AVERAGE(C18:L18),0) -> 0.064721382 | O18: =IFERROR(AVERAGE(D18:M18),0) -> 0.064088797
B19: OprIncome%Sales | C19: =C13 -> 0.090632289 | D19: =D13 -> 0.12359393 | E19: =E13 -> 0.13416539 | F19: =F13 -> 0.15045193 | G19: =G13 -> 0.17530126 | H19: =H13 -> 0.17660061 | I19: =I13 -> 0.18141671 | J19: =J13 -> 0.20141371 | ... L19: =L13 -> 0.24161882 | N19: =IFERROR(AVERAGE(C19:L19),0) -> 0.17477307 | O19: =IFERROR(AVERAGE(D19:M19),0) -> 0.18412204
B21: Return on Cap Emp | C21: =IFERROR((HistoricalFS!C29)/(SUM(HistoricalFS!C53:C55)),0) -> 0.096953865 | D21: =IFERROR((HistoricalFS!D29)/(SUM(HistoricalFS!D53:D55)),0) -> 0.14068619 | E21: =IFERROR((HistoricalFS!E29)/(SUM(HistoricalFS!E53:E55)),0) -> 0.14859137 | F21: =IFERROR((HistoricalFS!F29)/(SUM(HistoricalFS!F53:F55)),0) -> 0.15147011 | G21: =IFERROR((HistoricalFS!G29)/(SUM(HistoricalFS!G53:G55)),0) -> 0.1863011 | H21: =IFERROR((HistoricalFS!H29)/(SUM(HistoricalFS!H53:H55)),0) -> 0.16796307 | I21: =IFERROR((HistoricalFS!I29)/(SUM(HistoricalFS!I53:I55)),0) -> 0.21478407 | J21: =IFERROR((HistoricalFS!J29)/(SUM(HistoricalFS!J53:J55)),0) -> 0.18522648 | ... L21: =IFERROR((HistoricalFS!L29)/(SUM(HistoricalFS!L53:L55)),0) -> 0.087900338 | N21: =IFERROR(AVERAGE(C21:L21),0) -> 0.15825805 | O21: =IFERROR(AVERAGE(D21:M21),0) -> 0.16506963
B22: Retained Earn % | C22: =IFERROR(HistoricalFS!C49,0) -> 1.1016337 | D22: =IFERROR(HistoricalFS!D49,0) -> 1.0322951 | E22: =IFERROR(HistoricalFS!E49,0) -> 1.0295587 | F22: =IFERROR(HistoricalFS!F49,0) -> 1.0370878 | G22: =IFERROR(HistoricalFS!G49,0) -> 1.0294339 | H22: =IFERROR(HistoricalFS!H49,0) -> 1.0243539 | I22: =IFERROR(HistoricalFS!I49,0) -> 1.0205712 | J22: =IFERROR(HistoricalFS!J49,0) -> 1.0119132 | ... L22: =IFERROR(HistoricalFS!L49,0) -> 1.019847 | N22: =IFERROR(AVERAGE(C22:L22),0) -> 1.0315168 | O22: =IFERROR(AVERAGE(D22:M22),0) -> 1.023726
B23: Return on Equity% | C23: =IFERROR(HistoricalFS!C38/SUM(HistoricalFS!C53:C54),0) -> 0.084983782 | D23: =IFERROR(HistoricalFS!D38/SUM(HistoricalFS!D53:D54),0) -> 0.16608765 | E23: =IFERROR(HistoricalFS!E38/SUM(HistoricalFS!E53:E54),0) -> 0.14504661 | F23: =IFERROR(HistoricalFS!F38/SUM(HistoricalFS!F53:F54),0) -> 0.12145503 | G23: =IFERROR(HistoricalFS!G38/SUM(HistoricalFS!G53:G54),0) -> 0.12137289 | H23: =IFERROR(HistoricalFS!H38/SUM(HistoricalFS!H53:H54),0) -> 0.12401029 | I23: =IFERROR(HistoricalFS!I38/SUM(HistoricalFS!I53:I54),0) -> 0.12296344 | J23: =IFERROR(HistoricalFS!J38/SUM(HistoricalFS!J53:J54),0) -> 0.16603126 | ... L23: =IFERROR(HistoricalFS!L38/SUM(HistoricalFS!L53:L54),0) -> 0.071241093 | N23: =IFERROR(AVERAGE(C23:L23),0) -> 0.13058957 | O23: =IFERROR(AVERAGE(D23:M23),0) -> 0.13565688
B24: Self Sust Growth Rate | C24: =IFERROR(C22*C23,0) -> 0.093620995 | D24: =IFERROR(D22*D23,0) -> 0.17145148 | E24: =IFERROR(E22*E23,0) -> 0.149334 | F24: =IFERROR(F22*F23,0) -> 0.12595953 | G24: =IFERROR(G22*G23,0) -> 0.12494537 | H24: =IFERROR(H22*H23,0) -> 0.12703043 | I24: =IFERROR(I22*I23,0) -> 0.12549295 | J24: =IFERROR(J22*J23,0) -> 0.16800923 | ... L24: =IFERROR(L22*L23,0) -> 0.072655013 | N24: =IFERROR(AVERAGE(C24:L24),0) -> 0.13427507 | O24: =IFERROR(AVERAGE(D24:M24),0) -> 0.13879219
B25: Interest Cov Ratio | C25: =IFERROR((HistoricalFS!C18-HistoricalFS!C26)/HistoricalFS!C23,0) -> 2.0480253 | D25: =IFERROR((HistoricalFS!D18-HistoricalFS!D26)/HistoricalFS!D23,0) -> 3.1004848 | E25: =IFERROR((HistoricalFS!E18-HistoricalFS!E26)/HistoricalFS!E23,0) -> 3.4220837 | F25: =IFERROR((HistoricalFS!F18-HistoricalFS!F26)/HistoricalFS!F23,0) -> 3.3296624 | G25: =IFERROR((HistoricalFS!G18-HistoricalFS!G26)/HistoricalFS!G23,0) -> 3.8211095 | H25: =IFERROR((HistoricalFS!H18-HistoricalFS!H26)/HistoricalFS!H23,0) -> 4.213246 | I25: =IFERROR((HistoricalFS!I18-HistoricalFS!I26)/HistoricalFS!I23,0) -> 4.8043025 | J25: =IFERROR((HistoricalFS!J18-HistoricalFS!J26)/HistoricalFS!J23,0) -> 8.4253471 | ... L25: =IFERROR((HistoricalFS!L18-HistoricalFS!L26)/HistoricalFS!L23,0) -> 3.078874 | N25: =IFERROR(AVERAGE(C25:L25),0) -> 4.2470769 | O25: =IFERROR(AVERAGE(D25:M25),0) -> 4.4914159
B27: Debt Turnover Ratio | C27: =IFERROR(HistoricalFS!C6/HistoricalFS!C65,0) -> 9.0380869 | D27: =IFERROR(HistoricalFS!D6/HistoricalFS!D65,0) -> 7.6896782 | E27: =IFERROR(HistoricalFS!E6/HistoricalFS!E65,0) -> 23.672521 | F27: =IFERROR(HistoricalFS!F6/HistoricalFS!F65,0) -> 14.037675 | G27: =IFERROR(HistoricalFS!G6/HistoricalFS!G65,0) -> 8.723015 | H27: =IFERROR(HistoricalFS!H6/HistoricalFS!H65,0) -> 6.025668 | I27: =IFERROR(HistoricalFS!I6/HistoricalFS!I65,0) -> 6.5216889 | J27: =IFERROR(HistoricalFS!J6/HistoricalFS!J65,0) -> 6.5721386 | ... L27: =IFERROR(HistoricalFS!L6/HistoricalFS!L65,0) -> 3.3376342 | N27: =IFERROR(AVERAGE(C27:L27),0) -> 9.0778313 | O27: =IFERROR(AVERAGE(D27:M27),0) -> 9.0822473
B28: Creditor Turnover Ratio | C28: =IFERROR(HistoricalFS!C6/HistoricalFS!C56,0) -> 2.3222463 | D28: =IFERROR(HistoricalFS!D6/HistoricalFS!D56,0) -> 2.6203439 | E28: =IFERROR(HistoricalFS!E6/HistoricalFS!E56,0) -> 3.4718119 | F28: =IFERROR(HistoricalFS!F6/HistoricalFS!F56,0) -> 2.2952796 | G28: =IFERROR(HistoricalFS!G6/HistoricalFS!G56,0) -> 2.2773747 | H28: =IFERROR(HistoricalFS!H6/HistoricalFS!H56,0) -> 2.4378803 | I28: =IFERROR(HistoricalFS!I6/HistoricalFS!I56,0) -> 4.4604557 | J28: =IFERROR(HistoricalFS!J6/HistoricalFS!J56,0) -> 4.4869226 | ... L28: =IFERROR(HistoricalFS!L6/HistoricalFS!L56,0) -> 3.8252825 | N28: =IFERROR(AVERAGE(C28:L28),0) -> 3.4614643 | O28: =IFERROR(AVERAGE(D28:M28),0) -> 3.5880441
B29: Invt Turnover | C29: =HistoricalFS!C6/HistoricalFS!C66 -> 20.388999 | D29: =HistoricalFS!D6/HistoricalFS!D66 -> 27.576282 | E29: =HistoricalFS!E6/HistoricalFS!E66 -> 22.645518 | F29: =HistoricalFS!F6/HistoricalFS!F66 -> 19.906463 | G29: =HistoricalFS!G6/HistoricalFS!G66 -> 19.620447 | H29: =HistoricalFS!H6/HistoricalFS!H66 -> 15.856031 | I29: =HistoricalFS!I6/HistoricalFS!I66 -> 17.343466 | J29: =HistoricalFS!J6/HistoricalFS!J66 -> 20.054738 | ... L29: =HistoricalFS!L6/HistoricalFS!L66 -> 20.314811 | N29: =IFERROR(AVERAGE(C29:L29),0) -> 21.333814 | O29: =IFERROR(AVERAGE(D29:M29),0) -> 21.438793
B30: Fixed Asset Turnover | C30: =IFERROR(HistoricalFS!C6/HistoricalFS!C59,0) -> 1.3367604 | D30: =IFERROR(HistoricalFS!D6/HistoricalFS!D59,0) -> 1.5429232 | E30: =IFERROR(HistoricalFS!E6/HistoricalFS!E59,0) -> 1.7353012 | F30: =IFERROR(HistoricalFS!F6/HistoricalFS!F59,0) -> 1.9231578 | G30: =IFERROR(HistoricalFS!G6/HistoricalFS!G59,0) -> 3.7417912 | H30: =IFERROR(HistoricalFS!H6/HistoricalFS!H59,0) -> 4.0519384 | I30: =IFERROR(HistoricalFS!I6/HistoricalFS!I59,0) -> 4.5619378 | J30: =IFERROR(HistoricalFS!J6/HistoricalFS!J59,0) -> 5.4931916 | ... L30: =IFERROR(HistoricalFS!L6/HistoricalFS!L59,0) -> 6.2902406 | N30: =IFERROR(AVERAGE(C30:L30),0) -> 4.0529189 | O30: =IFERROR(AVERAGE(D30:M30),0) -> 4.3547142
B31: Capital Turnover Ratio | C31: =IFERROR(HistoricalFS!C6/SUM(HistoricalFS!C53:C54),0) -> 2.017557 | D31: =IFERROR(HistoricalFS!D6/SUM(HistoricalFS!D53:D54),0) -> 1.9752615 | E31: =IFERROR(HistoricalFS!E6/SUM(HistoricalFS!E53:E54),0) -> 1.7481424 | F31: =IFERROR(HistoricalFS!F6/SUM(HistoricalFS!F53:F54),0) -> 1.5709251 | G31: =IFERROR(HistoricalFS!G6/SUM(HistoricalFS!G53:G54),0) -> 1.4755567 | H31: =IFERROR(HistoricalFS!H6/SUM(HistoricalFS!H53:H54),0) -> 1.5490847 | I31: =IFERROR(HistoricalFS!I6/SUM(HistoricalFS!I53:I54),0) -> 1.4617012 | J31: =IFERROR(HistoricalFS!J6/SUM(HistoricalFS!J53:J54),0) -> 1.2462867 | ... L31: =IFERROR(HistoricalFS!L6/SUM(HistoricalFS!L53:L54),0) -> 0.54264188 | N31: =IFERROR(AVERAGE(C31:L31),0) -> 1.4633839 | O31: =IFERROR(AVERAGE(D31:M31),0) -> 1.4018091
B33: (in days)
B34: Debtor Days | C34: =IFERROR(365/C27,0) -> 40.384653 | D34: =IFERROR(365/D27,0) -> 47.466225 | E34: =IFERROR(365/E27,0) -> 15.418721 | F34: =IFERROR(365/F27,0) -> 26.001456 | G34: =IFERROR(365/G27,0) -> 41.843331 | H34: =IFERROR(365/H27,0) -> 60.574197 | I34: =IFERROR(365/I27,0) -> 55.967098 | J34: =IFERROR(365/J27,0) -> 55.537477 | ... L34: =IFERROR(365/L27,0) -> 109.3589 | N34: =IFERROR(AVERAGE(C34:L34),0) -> 52.328565 | O34: =IFERROR(AVERAGE(D34:M34),0) -> 53.655666
B35: Payable Days | C35: =IFERROR(365/C28,0) -> 157.17541 | D35: =IFERROR(365/D28,0) -> 139.29469 | E35: =IFERROR(365/E28,0) -> 105.13242 | F35: =IFERROR(365/F28,0) -> 159.02202 | G35: =IFERROR(365/G28,0) -> 160.27226 | H35: =IFERROR(365/H28,0) -> 149.72023 | I35: =IFERROR(365/I28,0) -> 81.830205 | J35: =IFERROR(365/J28,0) -> 81.347514 | ... L35: =IFERROR(365/L28,0) -> 95.417789 | N35: =IFERROR(AVERAGE(C35:L35),0) -> 118.60923 | O35: =IFERROR(AVERAGE(D35:M35),0) -> 114.3241
B36: Invt Days | C36: =IFERROR(365/C29,0) -> 17.90181 | D36: =IFERROR(365/D29,0) -> 13.236012 | E36: =IFERROR(365/E29,0) -> 16.117979 | F36: =IFERROR(365/F29,0) -> 18.335753 | G36: =IFERROR(365/G29,0) -> 18.603042 | H36: =IFERROR(365/H29,0) -> 23.019632 | I36: =IFERROR(365/I29,0) -> 21.04539 | J36: =IFERROR(365/J29,0) -> 18.200188 | ... L36: =IFERROR(365/L29,0) -> 17.967187 | N36: =IFERROR(AVERAGE(C36:L36),0) -> 17.674502 | O36: =IFERROR(AVERAGE(D36:M36),0) -> 17.649245
B37: Cash Conversion Cycle | C37: =SUM(C34,C36-C35) -> -98.888943 | D37: =SUM(D34,D36-D35) -> -78.592457 | E37: =SUM(E34,E36-E35) -> -73.595723 | F37: =SUM(F34,F36-F35) -> -114.68481 | G37: =SUM(G34,G36-G35) -> -99.82589 | H37: =SUM(H34,H36-H35) -> -66.126401 | I37: =SUM(I34,I36-I35) -> -4.8177168 | J37: =SUM(J34,J36-J35) -> -7.609849 | ... L37: =SUM(L34,L36-L35) -> 31.908295 | N37: =IFERROR(AVERAGE(C37:L37),0) -> -48.606163 | O37: =IFERROR(AVERAGE(D37:M37),0) -> -43.019188
B39: CFO/Sales | C39: =IFERROR(HistoricalFS!C115/HistoricalFS!C6,0) -> 0.2226803 | D39: =IFERROR(HistoricalFS!D115/HistoricalFS!D6,0) -> 0.10657615 | E39: =IFERROR(HistoricalFS!E115/HistoricalFS!E6,0) -> 0.11167794 | F39: =IFERROR(HistoricalFS!F115/HistoricalFS!F6,0) -> 0.09406611 | G39: =IFERROR(HistoricalFS!G115/HistoricalFS!G6,0) -> -0.026032931 | H39: =IFERROR(HistoricalFS!H115/HistoricalFS!H6,0) -> -0.093304713 | I39: =IFERROR(HistoricalFS!I115/HistoricalFS!I6,0) -> 0.29394982 | J39: =IFERROR(HistoricalFS!J115/HistoricalFS!J6,0) -> -0.0670777 | ... L39: =IFERROR(HistoricalFS!L115/HistoricalFS!L6,0) -> -0.055244421 | N39: =IFERROR(AVERAGE(C39:L39),0) -> 0.046809011 | O39: =IFERROR(AVERAGE(D39:M39),0) -> 0.027267756
B40: CFO/Total Assets | C40: =IFERROR(HistoricalFS!C115/HistoricalFS!C70,0) -> 0.16308609 | D40: =IFERROR(HistoricalFS!D115/HistoricalFS!D70,0) -> 0.084575035 | E40: =IFERROR(HistoricalFS!E115/HistoricalFS!E70,0) -> 0.093772215 | F40: =IFERROR(HistoricalFS!F115/HistoricalFS!F70,0) -> 0.065828609 | G40: =IFERROR(HistoricalFS!G115/HistoricalFS!G70,0) -> -0.01886364 | H40: =IFERROR(HistoricalFS!H115/HistoricalFS!H70,0) -> -0.06383661 | I40: =IFERROR(HistoricalFS!I115/HistoricalFS!I70,0) -> 0.27501779 | J40: =IFERROR(HistoricalFS!J115/HistoricalFS!J70,0) -> -0.051194133 | ... L40: =IFERROR(HistoricalFS!L115/HistoricalFS!L70,0) -> -0.018352408 | N40: =IFERROR(AVERAGE(C40:L40),0) -> 0.045058387 | O40: =IFERROR(AVERAGE(D40:M40),0) -> 0.031944198
B41: CFO/Total Debt | C41: =IFERROR(HistoricalFS!C115/HistoricalFS!C55,0) -> 0.50707214 | D41: =IFERROR(HistoricalFS!D115/HistoricalFS!D55,0) -> 0.28630582 | E41: =IFERROR(HistoricalFS!E115/HistoricalFS!E55,0) -> 0.33751863 | F41: =IFERROR(HistoricalFS!F115/HistoricalFS!F55,0) -> 0.26370435 | G41: =IFERROR(HistoricalFS!G115/HistoricalFS!G55,0) -> -0.098891898 | H41: =IFERROR(HistoricalFS!H115/HistoricalFS!H55,0) -> -0.22988097 | I41: =IFERROR(HistoricalFS!I115/HistoricalFS!I55,0) -> 1.8313192 | J41: =IFERROR(HistoricalFS!J115/HistoricalFS!J55,0) -> -0.23535376 | ... L41: =IFERROR(HistoricalFS!L115/HistoricalFS!L55,0) -> -0.060979851 | N41: =IFERROR(AVERAGE(C41:L41),0) -> 0.22944664 | O41: =IFERROR(AVERAGE(D41:M41),0) -> 0.19859937

Sheet CashFlow Data
C2: 42795 | D2: 43160 | E2: 43525 | F2: 43891 | G2: 44256 | H2: 44621 | I2: 44986 | J2: 45352 | K2: 45717 | L2: 46082
B3: Cash from Operating Activity - | C3: 30199 | D3: 23857 | E3: 18891 | F3: 26633 | G3: 29001 | H3: 14283 | I3: 35388 | J3: 67915 | K3: 63102 | L3: 13041
B4: Profit from operations | C4: 28840 | D4: 33312 | E4: 28771 | F4: 23352 | G4: 31198 | H4: 26943 | I4: 41694 | J4: 65106 | K4: 58937 | L4: 25393
B5: Receivables | C5: -4152 | D5: -10688 | E5: -9109 | F5: 9950 | G5: -5505 | H5: 185 | I5: -2213 | J5: -1876 | K5: 3573 | L5: -1587
B6: Inventory | C6: -6621 | D6: -3560 | E6: 2069 | F6: 2326 | G6: 3814 | H6: 472 | I6: -5665 | J6: -7265 | K6: 2127 | L6: -4318
B7: Payables | C7: 9301 | D7: 7320 | E7: -4692 | F7: -8085 | G7: 5748 | H7: -7012 | I7: 6945 | J7: 13706 | K7: 1303 | L7: -1973
B8: Loans Advances | C8: 0 | D8: 0 | E8: 0 | F8: 0 | G8: 0 | H8: 0 | I8: 0 | J8: 0 | K8: 0 | L8: -815
B9: Other WC items | C9: 4727 | D9: 494 | E9: 4512 | F9: 875 | G9: -4150 | H9: -4396 | I9: -2194 | J9: 2760 | K9: 1153 | L9: -345
B10: Working capital changes | C10: 3254 | D10: -6434 | E10: -7221 | F10: 5065 | G10: -93 | H10: -10750 | I10: -3127 | J10: 7325 | K10: 8156 | L10: -9038
B11: Direct taxes | C11: -1895 | D11: -3021 | E11: -2659 | F11: -1785 | G11: -2105 | H11: -1910 | I11: -3179 | J11: -4516 | K11: -3991 | L11: -3314
B12: Cash from Investing Activity - | C12: -39571 | D12: -25139 | E12: -20878 | F12: -33115 | G12: -25672 | H12: -4444 | I12: -15417 | J12: -22781 | K12: -49982 | L12: -24810
B13: Fixed assets purchased | C13: -16072 | D13: -35079 | E13: -35304 | F13: -29702 | G13: -20205 | H13: -15168 | I13: -19230 | J13: -31414 | K13: -38042 | L13: -36282
B14: Fixed assets sold | C14: 53 | D14: 30 | E14: 67 | F14: 171 | G14: 351 | H14: 230 | I14: 285 | J14: 231 | K14: 974 | L14: 46
... B35: CFO/OP | C35: 1.08 | D35: 0.85 | E35: 0.87 | F35: 1.58 | G35: 0.96 | H35: 0.66 | I35: 1.21 | J35: 1.25 | K35: 1.2 | L35: 0.87

Sheet Data Sheet
A1: COMPANY NAME | B1: KNR CONSTRUCTIONS LTD | E1: TATA Motors Ltd
A2: LATEST VERSION | B2: 2.1 | E2: PLEASE DO NOT MAKE ANY CHANGES TO THIS SHEET
A3: CURRENT VERSION | B3: 2.1
A5: META
A6: Number of shares | B6: =IF(B9>0, B9/B8, 0) -> 28.123283
A7: Face Value | B7: 2
A8: Current Price | B8: 126.7
A9: Market Capitalization | B9: 3563.22
A15: PROFIT & LOSS
A16: Report Date | B16: 42825 | C16: 43190 | D16: 43555 | E16: 43921 | F16: 44286 | G16: 44651 | H16: 45016 | I16: 45382 | J16: 45747 | K16: 46112
A17: Sales | B17: 1642.13 | C17: 2069.6 | D17: 2291.5 | E17: 2451.68 | F17: 2903.63 | G17: 3605.82 | H17: 4062.36 | I17: 4429.49 | J17: 4753.17 | K17: 2698.01
A18: Raw Material Cost | B18: 361.85 | C18: 506.86 | D18: 643.78 | E18: 753.28 | F18: 926.45 | G18: 1180.72 | H18: 1494.74 | I18: 1660.15 | J18: 1466.44 | K18: 770.27
A19: Change in Inventory | B19: -2.41 | C19: -5.98 | D19: 1.31
A20: Power and Fuel | B20: 5.19 | C20: 7.42 | D20: 10.33 | E20: 15.47 | F20: 17.23 | G20: 20.65 | H20: 20.23 | I20: 23.32 | J20: 21.5
A21: Other Mfr. Exp | B21: 881.9 | C21: 971.48 | D21: 964.67 | E21: 876.36 | F21: 1055.62 | G21: 1256.4 | H21: 1362.41 | I21: 1417.16 | J21: 1364.84
A22: Employee Cost | B22: 58.82 | C22: 74.29 | D22: 95.14 | E22: 127.35 | F22: 133.65 | G22: 146.48 | H22: 174.79 | I22: 174.71 | J22: 177.65 | K22: 152.09
A23: Selling and admin | B23: 95.34 | C23: 41.9 | D23: 32.58 | E23: 38.7 | F23: 32.47 | G23: 36.59 | H23: 47.26 | I23: 61.12 | J23: 57.51
A24: Other Expenses | B24: -27.84 | C24: 12.28 | D24: 8.74 | E24: 17.53 | F24: 39.3 | G24: 163.27 | H24: 45.25 | I24: 44.04 | J24: 55.6 | K24: 1064.3
A25: Other Income | B25: 29.57 | C25: 54.94 | D25: 74.76 | E25: 66.39 | F25: 143.99 | G25: 77.73 | H25: 97.67 | I25: 162.19 | J25: 172.18 | K25: 65.22
A26: Depreciation | B26: 115.63 | C26: 193.6 | D26: 230.13 | E26: 254.13 | F26: 189.9 | G26: 164.92 | H26: 180.7 | I26: 156.83 | J26: 314.22 | K26: 59.46
A27: Interest | B27: 72.67 | C27: 82.5 | D27: 89.84 | E27: 110.78 | F27: 133.21 | G27: 151.14 | H27: 153.4 | I27: 105.89 | J27: 208.01 | K27: 211.73
A28: Profit before tax | B28: 105.73 | C28: 228.23 | D28: 292.36 | E28: 324.47 | F28: 519.79 | G28: 563.38 | H28: 681.25 | I28: 948.46 | J28: 1259.58 | K28: 505.38
A29: Tax | B29: 6.99 | C29: -0.73 | D29: 27.47 | E29: 68.53 | F29: 136.96 | G29: 196.99 | H29: 241.84 | I29: 196.17 | J29: 257.71 | K29: 85.95
A30: Net profit | B30: 114.9 | C30: 243.48 | D30: 270.51 | E30: 265.51 | F30: 407.38 | G30: 381.84 | H30: 458.01 | I30: 777.4 | J30: 1001.87 | K30: 437.08
A31: Dividend Amount | B31: 7.03 | C31: 5.62 | D31: 5.62 | E31: 7.03 | F31: 7.03 | G31: 7.03 | H31: 7.03 | I31: 7.03 | J31: 7.03 | K31: 7.03
A40: Quarters
A41: Report Date | B41: 45291 | C41: 45382 | D41: 45473 | E41: 45565 | F41: 45657 | G41: 45747 | H41: 45838 | I41: 45930 | J41: 46022 | K41: 46112
A42: Sales | B42: 996.01 | C42: 1414 | D42: 985 | E42: 1944.86 | F42: 848.1 | G42: 975.21 | H42: 612.72 | I42: 646.5 | J42: 743.2 | K42: 695.59
A43: Expenses | B43: 770.1 | C43: 1039.48 | D43: 706.4 | E43: 1075.18 | F43: 592.52 | G43: 753.72 | H43: 429.77 | I43: 453.94 | J43: 576.49 | K43: 526.46
A44: Other Income | B44: 6.52 | C44: 125.25 | D44: 20.9 | E44: 132.19 | F44: 122.3 | G44: -100.32 | H44: 25.24 | I44: 7.48 | J44: 13.55 | K44: 18.96
A45: Depreciation | B45: 40.68 | C45: 40.54 | D45: 30.07 | E45: 237.93 | F45: 23.36 | G45: 22.86 | H45: 15.42 | I45: 15.09 | J45: 15.01 | K45: 13.94
A46: Interest | B46: 27.66 | C46: 37.07 | D46: 37.13 | E46: 88.74 | F46: 41.43 | G46: 40.58 | H46: 48.35 | I46: 52.73 | J46: 54.85 | K46: 55.8
A47: Profit before tax | B47: 164.09 | C47: 422.16 | D47: 232.3 | E47: 675.2 | F47: 313.09 | G47: 57.73 | H47: 144.42 | I47: 132.22 | J47: 110.4 | K47: 118.35
A48: Tax | B48: 28.26 | C48: 94.65 | D48: 54.64 | E48: 90.14 | F48: 62.52 | G48: 50.42 | H48: 23.25 | I48: 29.37 | J48: 8.6 | K48: 24.72
A49: Net profit | B49: 139.61 | C49: 353.3 | D49: 172.58 | E49: 441.47 | F49: 248.59 | G49: 139.24 | H49: 123.41 | I49: 104.66 | J49: 102.8 | K49: 106.21
A50: Operating Profit | B50: 225.91 | C50: 374.52 | D50: 278.6 | E50: 869.68 | F50: 255.58 | G50: 221.49 | H50: 182.95 | I50: 192.56 | J50: 166.71 | K50: 169.13
A55: BALANCE SHEET
A56: Report Date | B56: 42825 | C56: 43190 | D56: 43555 | E56: 43921 | F56: 44286 | G56: 44651 | H56: 45016 | I56: 45382 | J56: 45747 | K56: 46112
A57: Equity Share Capital | B57: 28.12 | C57: 28.12 | D57: 28.12 | E57: 28.12 | F57: 56.25 | G57: 56.25 | H57: 56.25 | I57: 56.25 | J57: 56.25 | K57: 56.25
A58: Reserves | B58: 785.8 | C58: 1019.64 | D58: 1282.7 | E58: 1532.54 | F58: 1911.57 | G58: 2271.46 | H58: 2722.95 | I58: 3497.9 | J58: 4484.93 | K58: 4915.74
...

Sheet Forecast
B1: Tata Motors
B2: Year Weight | C2: Year | D2: Sales | E2: Sales Growth
B3: 1 | C3: 2015 | D3: 263159
B4: =B3+1 -> 2 | C4: =C3+1 -> 2016 | D4: 273046 | E4: =D4/D3-1 -> 0.037570442
B5: =B4+1 -> 3 | C5: =C4+1 -> 2017 | D5: 269693 | E5: =D5/D4-1 -> -0.012279982
B6: =B5+1 -> 4 | C6: =C5+1 -> 2018 | D6: 291550 | E6: =D6/D5-1 -> 0.081044002
B7: =B6+1 -> 5 | C7: =C6+1 -> 2019 | D7: 301938 | E7: =D7/D6-1 -> 0.035630252
B8: =B7+1 -> 6 | C8: =C7+1 -> 2020 | D8: 261068 | E8: =D8/D7-1 -> -0.13535891
B9: =B8+1 -> 7 | C9: =C8+1 -> 2021 | D9: 249795 | E9: =D9/D8-1 -> -0.043180321
B10: =B9+1 -> 8 | C10: =C9+1 -> 2022 | D10: 278454 | E10: =D10/D9-1 -> 0.11473008 | G10: SUMMARY OUTPUT
B11: =B10+1 -> 9 | C11: =C10+1 -> 2023 | D11: 345967 | E11: =D11/D10-1 -> 0.24245656
B12: =B11+1 -> 10 | C12: =C11+1 -> 2024 | D12: 434016 | E12: =D12/D11-1 -> 0.25450115 | G12: Regression Statistics
B13: =B12+1 -> 11 | C13: =C12+1 -> 2025 | D13: 439695 | E13: =D13/D12-1 -> 0.013084771 | G13: Multiple R | H13: 0.70368468
B14: =B13+1 -> 12 | C14: =C13+1 -> 2026 | D14: 335582 | E14: =D14/D13-1 -> -0.23678459 | G14: R Square | H14: 0.49517212 | I14: Strength of regr should be more than 0.4
B15: =B14+1 -> 13 | C15: =C14+1 -> 2027 | D15: =FORECAST(B15,$D$3:$D$14,$B$3:$B$14) -> 394658.62 | E15: =D15/D14-1 -> 0.17604228 | G15: Adjusted R Square | H15: 0.44468934
B16: =B15+1 -> 14 | C16: =C15+1 -> 2028 | D16: =FORECAST(B16,$D$3:$D$14,$B$3:$B$14) -> 407375.81 | E16: =D16/D15-1 -> 0.032223255 | G16: Standard Error | H16: 48557.083
B17: =B16+1 -> 15 | C17: =C16+1 -> 2029 | D17: =FORECAST(B17,$D$3:$D$14,$B$3:$B$14) -> 420092.99 | E17: =D17/D16-1 -> 0.031217331 | G17: Observations | H17: 12
B18: =B17+1 -> 16 | C18: =C17+1 -> 2030 | D18: =FORECAST(B18,$D$3:$D$14,$B$3:$B$14) -> 432810.18 | E18: =D18/D17-1 -> 0.03027231
B19: =B18+1 -> 17 | C19: =C18+1 -> 2031 | D19: =FORECAST(B19,$D$3:$D$14,$B$3:$B$14) -> 445527.36 | E19: =D19/D18-1 -> 0.029382824 | G19: ANOVA
H20: df | I20: SS | J20: MS | K20: F | L20: Significance F
G21: Regression | H21: 1 | I21: 2.3126933e+10 | J21: 2.3126933e+10 | K21: 9.8087318 | L21: 0.01065618
B22: 13 | C22: 2027 | D22: 394658.62 | E22: 0.17604228 | G22: Residual | H22: 10 | I22: 2.3577903e+10 | J22: 2.3577903e+09
B23: 14 | C23: 2028 | D23: 407375.81 | E23: 0.032223255 | G23: Total | H23: 11 | I23: 4.6704836e+10
B24: 15 | C24: 2029 | D24: 420092.99 | E24: 0.031217331
B25: 16 | C25: 2030 | D25: 432810.18 | E25: 0.03027231 | H25: Coefficients | I25: Standard Error | J25: t Stat | K25: P-value | L25: Lower 95% | M25: Upper 95% | N25: Lower 95.0% | O25: Upper 95.0%
B26: 17 | C26: 2031 | D26: 445527.36 | E26: 0.029382824 | G26: Intercept | H26: 229335.21 | I26: 29884.819 | J26: 7.6739703 | K26: 1.6920326e-05 | L26: 162747.69 | M26: 295922.74 | N26: 162747.69 | O26: 295922.74
G27: Year Weight | H27: 12717.185 | I27: 4060.5473 | J27: 3.1318895 | K27: 0.01065618 | L27: 3669.7222 | M27: 21764.648 | N27: 3669.7222 | O27: 21764.648

Sheet Sheet2
B2: ='Data Sheet'!$B$1&" - "&'Data Sheet'!$A$17&" Forecasting" -> KNR CONSTRUCTIONS LTD - Sales Forecasting | G2: ='Data Sheet'!$B$1&" - "&HistoricalFS!B18&" Forecasting" -> KNR CONSTRUCTIONS LTD - EBITDA Forecasting | L2: ='Data Sheet'!$B$1&" - "&HistoricalFS!B43&" Forecasting" -> KNR CONSTRUCTIONS LTD - EPS Forecasting
B3: Year Weight | C3: Year | D3: Sales | E3: Sales Growth | G3: Year Weight | H3: Year | I3: EBITDA | J3: Sales Growth | L3: Year Weight | M3: Year | N3: EBITDA | O3: Sales Growth
B4: 1 | C4: ='Data Sheet'!$B$16 -> 42825 | D4: {=TRANSPOSE('Data Sheet'!B17:K17)} -> 1642.13 | G4: 1 | H4: ='Data Sheet'!$B$16 -> 42825 | I4: {=TRANSPOSE(HistoricalFS!C18:L18)} -> 264.46 | L4: 1 | M4: ='Data Sheet'!$B$16 -> 42825 | N4: {=TRANSPOSE(HistoricalFS!C43:L43)} -> 2.4598151
B5: =B4+1 -> 2 | C5: =C4+365 -> 43190 | D5: 2069.6 | E5: =D5/D4-1 -> 0.26031435 | G5: =G4+1 -> 2 | H5: =H4+365 -> 43190 | I5: 449.39 | J5: =I5/I4-1 -> 0.69927399 | L5: =L4+1 -> 2 | M5: =M4+365 -> 43190 | N5: 6.188478 | O5: =N5/N4-1 -> 1.5158306
B6: =B5+1 -> 3 | C6: =C5+365 -> 43555 | D6: 2291.5 | E6: =D6/D5-1 -> 0.10721879 | G6: =G5+1 -> 3 | H6: =H5+365 -> 43555 | I6: 537.57 | J6: =I6/I5-1 -> 0.19622154 | L6: =L5+1 -> 3 | M6: =M5+365 -> 43555 | N6: 6.7613798 | O6: =N6/N5-1 -> 0.092575566
B7: =B6+1 -> 4 | C7: =C6+365 -> 43920 | D7: 2451.68 | E7: =D7/D6-1 -> 0.069901811 | G7: =G6+1 -> 4 | H7: =H6+365 -> 43920 | I7: 622.99 | J7: =I7/I6-1 -> 0.15890024 | L7: =L6+1 -> 4 | M7: =M6+365 -> 43920 | N7: 6.7407539 | O7: =N7/N6-1 -> -0.0030505444
B8: =B7+1 -> 5 | C8: =C7+365 -> 44285 | D8: 2903.63 | E8: =D8/D7-1 -> 0.18434298 | G8: =G7+1 -> 5 | H8: =H7+365 -> 44285 | I8: 698.91 | J8: =I8/I7-1 -> 0.12186391 | L8: =L7+1 -> 5 | M8: =M7+365 -> 44285 | N8: 8.4935989 | O8: =N8/N7-1 -> 0.26003693
B9: =B8+1 -> 6 | C9: =C8+365 -> 44650 | D9: 3605.82 | E9: =D9/D8-1 -> 0.24183178 | G9: =G8+1 -> 6 | H9: =H8+365 -> 44650 | I9: 801.71 | J9: =I9/I8-1 -> 0.14708618 | L9: =L8+1 -> 6 | M9: =M8+365 -> 44650 | N9: 10.265292 | O9: =N9/N8-1 -> 0.20859153
B10: =B9+1 -> 7 | C10: =C9+365 -> 45015 | D10: 4062.36 | E10: =D10/D9-1 -> 0.12661198 | G10: =G9+1 -> 7 | H10: =H9+365 -> 45015 | I10: 917.68 | J10: =I10/I9-1 -> 0.1446533 | L10: =L9+1 -> 7 | M10: =M9+365 -> 45015 | N10: 12.152916 | O10: =N10/N9-1 -> 0.18388415
B11: =B10+1 -> 8 | C11: =C10+365 -> 45380 | D11: 4429.49 | E11: =D11/D10-1 -> 0.090373576 | G11: =G10+1 -> 8 | H11: =H10+365 -> 45380 | I11: 1048.99 | J11: =I11/I10-1 -> 0.14308909 | L11: =L10+1 -> 8 | M11: =M10+365 -> 45380 | N11: 20.985064 | O11: =N11/N10-1 -> 0.72675133
B12: =B11+1 -> 9 | C12: =C11+365 -> 45745 | D12: 4753.17 | E12: =D12/D11-1 -> 0.073073875 | G12: =G11+1 -> 9 | H12: =H11+365 -> 45745 | I12: 1609.63 | J12: =I12/I11-1 -> 0.53445695 | L12: =L11+1 -> 9 | M12: =M11+365 -> 45745 | N12: 29.505334 | O12: =N12/N11-1 -> 0.40601593
B13: =B12+1 -> 10 | C13: =C12+365 -> 46110 | D13: 2698.01 | E13: =D13/D12-1 -> -0.43237671 | G13: =G12+1 -> 10 | H13: =H12+365 -> 46110 | I13: 711.35 | J13: =I13/I12-1 -> -0.55806614 | L13: =L12+1 -> 10 | M13: =M12+365 -> 46110 | N13: 12.596373 | O13: =N13/N12-1 -> -0.57308151
B14: =B13+1 -> 11 | C14: =C13+365 -> 46475 | D14: =FORECAST(B14,$D$4:$D$13,$B$4:$B$13) -> 4574.4753 | E14: =D14/D13-1 -> 0.69549977 | G14: =G13+1 -> 11 | H14: =H13+365 -> 46475 | I14: =FORECAST(G14,$I$4:$I$13,$G$4:$G$13) -> 1289.19 | J14: =I14/I13-1 -> 0.81231461 | L14: =L13+1 -> 11 | M14: =M13+365 -> 46475 | N14: =FORECAST(L14,$N$4:$N$13,$L$4:$L$13) -> 23.067354 | O14: =N14/N13-1 -> 0.83126959
B15: =B14+1 -> 12 | C15: =C14+365 -> 46840 | D15: =FORECAST(B15,$D$4:$D$13,$B$4:$B$13) -> 4844.2456 | E15: =D15/D14-1 -> 0.058972936 | G15: =G14+1 -> 12 | H15: =H14+365 -> 46840 | I15: =FORECAST(G15,$I$4:$I$13,$G$4:$G$13) -> 1384.2667 | J15: =I15/I14-1 -> 0.073749197 | L15: =L14+1 -> 12 | M15: =M14+365 -> 46840 | N15: =FORECAST(L15,$N$4:$N$13,$L$4:$L$13) -> 25.149619 | O15: =N15/N14-1 -> 0.090268884
B16: =B15+1 -> 13 | C16: =C15+365 -> 47205 | D16: =FORECAST(B16,$D$4:$D$13,$B$4:$B$13) -> 5114.0158 | E16: =D16/D15-1 -> 0.055688804 | G16: =G15+1 -> 13 | H16: =H15+365 -> 47205 | I16: =FORECAST(G16,$I$4:$I$13,$G$4:$G$13) -> 1479.3435 | J16: =I16/I15-1 -> 0.06868382 | L16: =L15+1 -> 13 | M16: =M15+365 -> 47205 | N16: =FORECAST(L16,$N$4:$N$13,$L$4:$L$13) -> 27.231883 | O16: =N16/N15-1 -> 0.082795066
B17: =B16+1 -> 14 | C17: =C16+365 -> 47570 | D17: =FORECAST(B17,$D$4:$D$13,$B$4:$B$13) -> 5383.7861 | E17: =D17/D16-1 -> 0.052751155 | G17: =G16+1 -> 14 | H17: =H16+365 -> 47570 | I17: =FORECAST(G17,$I$4:$I$13,$G$4:$G$13) -> 1574.4202 | J17: =I17/I16-1 -> 0.064269543 | L17: =L16+1 -> 14 | M17: =M16+365 -> 47570 | N17: =FORECAST(L17,$N$4:$N$13,$L$4:$L$13) -> 29.314147 | O17: =N17/N16-1 -> 0.076464207
B18: =B17+1 -> 15 | C18: =C17+365 -> 47935 | D18: =FORECAST(B18,$D$4:$D$13,$B$4:$B$13) -> 5653.5563 | E18: =D18/D17-1 -> 0.050107905 | G18: =G17+1 -> 15 | H18: =H17+365 -> 47935 | I18: =FORECAST(G18,$I$4:$I$13,$G$4:$G$13) -> 1669.4969 | J18: =I18/I17-1 -> 0.060388407 | L18: =L17+1 -> 15 | M18: =M17+365 -> 47935 | N18: =FORECAST(L18,$N$4:$N$13,$L$4:$L$13) -> 31.396411 | O18: =N18/N17-1 -> 0.071032744
