Workbook
Name UPDATE: 'Data Sheet'!$E$1

Sheet Profit & Loss
A1: ='Data Sheet'!B1 -> WAAREE ENERGIES LTD | H1: =UPDATE -> WAAREE ENERGIES LTD | M1: SCREENER.IN
A3: Narration | B3: ='Data Sheet'!B16 -> 42825 | C3: ='Data Sheet'!C16 -> 43190 | D3: ='Data Sheet'!D16 -> 43555 | E3: ='Data Sheet'!E16 -> 43921 | F3: ='Data Sheet'!F16 -> 44286 | G3: ='Data Sheet'!G16 -> 44651 | H3: ='Data Sheet'!H16 -> 45016 | I3: ='Data Sheet'!I16 -> 45382 | ... K3: ='Data Sheet'!K16 -> 46112 | L3: Trailing | M3: Best Case | N3: Worst Case
A4: Sales | B4: ='Data Sheet'!B17 -> 0 | C4: ='Data Sheet'!C17 -> 0 | D4: ='Data Sheet'!D17 -> 0 | E4: ='Data Sheet'!E17 -> 1995.78 | F4: ='Data Sheet'!F17 -> 1952.78 | G4: ='Data Sheet'!G17 -> 2854.27 | H4: ='Data Sheet'!H17 -> 6750.87 | I4: ='Data Sheet'!I17 -> 11397.61 | ... K4: ='Data Sheet'!K17 -> 26536.77 | L4: =SUM('Data Sheet'!H42:K42) -> 26536.77 | M4: =$K4+M23*K4 -> 48752.131 | N4: =$K4+N23*L4 -> 41880.401
A5: Expenses | B5: =SUM('Data Sheet'!B18,'Data Sheet'!B20:B24, -1*'Data Sheet'!B19) -> 0 | C5: =SUM('Data Sheet'!C18,'Data Sheet'!C20:C24, -1*'Data Sheet'!C19) -> 0 | D5: =SUM('Data Sheet'!D18,'Data Sheet'!D20:D24, -1*'Data Sheet'!D19) -> 0 | E5: =SUM('Data Sheet'!E18,'Data Sheet'!E20:E24, -1*'Data Sheet'!E19) -> 1903.01 | F5: =SUM('Data Sheet'!F18,'Data Sheet'!F20:F24, -1*'Data Sheet'!F19) -> 1867.95 | G5: =SUM('Data Sheet'!G18,'Data Sheet'!G20:G24, -1*'Data Sheet'!G19) -> 2748.32 | H5: =SUM('Data Sheet'!H18,'Data Sheet'!H20:H24, -1*'Data Sheet'!H19) -> 5915.06 | I5: =SUM('Data Sheet'!I18,'Data Sheet'!I20:I24, -1*'Data Sheet'!I19) -> 9823.18 | ... K5: =SUM('Data Sheet'!K18,'Data Sheet'!K20:K24, -1*'Data Sheet'!K19) -> 20628.13 | L5: =SUM('Data Sheet'!H43:K43) -> 20628.14 | M5: =M4-M6 -> 37897.069 | N5: =N4-N6 -> 34687.347
A6: Operating Profit | B6: =B4-B5 -> 0 | C6: =C4-C5 -> 0 | D6: =D4-D5 -> 0 | E6: =E4-E5 -> 92.77 | F6: =F4-F5 -> 84.83 | G6: =G4-G5 -> 105.95 | H6: =H4-H5 -> 835.81 | I6: =I4-I5 -> 1574.43 | ... K6: =K4-K5 -> 5908.64 | L6: =SUM('Data Sheet'!H50:K50) -> 5908.63 | M6: =M4*M24 -> 10855.063 | N6: =N4*N24 -> 7193.0538
A7: Other Income | B7: ='Data Sheet'!B25 -> 0 | C7: ='Data Sheet'!C25 -> 0 | D7: ='Data Sheet'!D25 -> 0 | E7: ='Data Sheet'!E25 -> 25.01 | F7: ='Data Sheet'!F25 -> 44.65 | G7: ='Data Sheet'!G25 -> 96.58 | H7: ='Data Sheet'!H25 -> 87.74 | I7: ='Data Sheet'!I25 -> 576.49 | ... K7: ='Data Sheet'!K25 -> 413.37 | L7: =SUM(#REF!) -> #REF! | M7: 0 | N7: 0
A8: Depreciation | B8: ='Data Sheet'!B26 -> 0 | C8: ='Data Sheet'!C26 -> 0 | D8: ='Data Sheet'!D26 -> 0 | E8: ='Data Sheet'!E26 -> 27.13 | F8: ='Data Sheet'!F26 -> 28.66 | G8: ='Data Sheet'!G26 -> 43.27 | H8: ='Data Sheet'!H26 -> 164.13 | I8: ='Data Sheet'!I26 -> 276.81 | ... K8: ='Data Sheet'!K26 -> 989.72 | L8: =SUM(#REF!) -> #REF! | M8: =+$L8 -> #REF! | N8: =+$L8 -> #REF!
A9: Interest | B9: ='Data Sheet'!B27 -> 0 | C9: ='Data Sheet'!C27 -> 0 | D9: ='Data Sheet'!D27 -> 0 | E9: ='Data Sheet'!E27 -> 33.71 | F9: ='Data Sheet'!F27 -> 30.92 | G9: ='Data Sheet'!G27 -> 40.88 | H9: ='Data Sheet'!H27 -> 82.27 | I9: ='Data Sheet'!I27 -> 139.91 | ... K9: ='Data Sheet'!K27 -> 280.5 | L9: =SUM(#REF!) -> #REF! | M9: =+$L9 -> #REF! | N9: =+$L9 -> #REF!
A10: Profit before tax | B10: ='Data Sheet'!B28 -> 0 | C10: ='Data Sheet'!C28 -> 0 | D10: ='Data Sheet'!D28 -> 0 | E10: ='Data Sheet'!E28 -> 56.94 | F10: ='Data Sheet'!F28 -> 69.9 | G10: ='Data Sheet'!G28 -> 118.38 | H10: ='Data Sheet'!H28 -> 677.15 | I10: ='Data Sheet'!I28 -> 1734.2 | ... K10: ='Data Sheet'!K28 -> 5051.79 | L10: =SUM(#REF!) -> #REF! | M10: =M6+M7-SUM(M8:M9) -> #REF! | N10: =N6+N7-SUM(N8:N9) -> #REF!
A11: Tax | B11: ='Data Sheet'!B29 -> 0 | C11: ='Data Sheet'!C29 -> 0 | D11: ='Data Sheet'!D29 -> 0 | E11: ='Data Sheet'!E29 -> 17.92 | F11: ='Data Sheet'!F29 -> 21.72 | G11: ='Data Sheet'!G29 -> 38.72 | H11: ='Data Sheet'!H29 -> 176.88 | I11: ='Data Sheet'!I29 -> 459.82 | ... K11: ='Data Sheet'!K29 -> 1167.64 | L11: =SUM(#REF!) -> #REF! | M11: =IF($L10>0,$L11/$L10,0) -> #REF! | N11: =IF($L10>0,$L11/$L10,0) -> #REF!
A12: Net profit | B12: ='Data Sheet'!B30 -> 0 | C12: ='Data Sheet'!C30 -> 0 | D12: ='Data Sheet'!D30 -> 0 | E12: ='Data Sheet'!E30 -> 41.71 | F12: ='Data Sheet'!F30 -> 49.21 | G12: ='Data Sheet'!G30 -> 75.64 | H12: ='Data Sheet'!H30 -> 482.76 | I12: ='Data Sheet'!I30 -> 1237.18 | ... K12: ='Data Sheet'!K30 -> 3711.3 | L12: =SUM(#REF!) -> #REF! | M12: =M10-M11*M10 -> #REF! | N12: =N10-N11*N10 -> #REF!
A13: EPS | B13: =IF('Data Sheet'!B93>0,B12/'Data Sheet'!B93,0) -> 0 | C13: =IF('Data Sheet'!C93>0,C12/'Data Sheet'!C93,0) -> 0 | D13: =IF('Data Sheet'!D93>0,D12/'Data Sheet'!D93,0) -> 0 | E13: =IF('Data Sheet'!E93>0,E12/'Data Sheet'!E93,0) -> 2.1161847 | F13: =IF('Data Sheet'!F93>0,F12/'Data Sheet'!F93,0) -> 2.4967022 | G13: =IF('Data Sheet'!G93>0,G12/'Data Sheet'!G93,0) -> 3.8376459 | H13: =IF('Data Sheet'!H93>0,H12/'Data Sheet'!H93,0) -> 24.493151 | I13: =IF('Data Sheet'!I93>0,I12/'Data Sheet'!I93,0) -> 62.769153 | ... K13: =IF('Data Sheet'!K93>0,K12/'Data Sheet'!K93,0) -> 128.99896 | L13: =IF('Data Sheet'!$B6>0,'Profit & Loss'!L12/'Data Sheet'!$B6,0) -> #REF! | M13: =IF('Data Sheet'!$B6>0,'Profit & Loss'!M12/'Data Sheet'!$B6,0) -> #REF! | N13: =IF('Data Sheet'!$B6>0,'Profit & Loss'!N12/'Data Sheet'!$B6,0) -> #REF!
A14: Price to earning | B14: =IF(B15>0,B15/B13,"") | C14: =IF(C15>0,C15/C13,"") | D14: =IF(D15>0,D15/D13,"") | E14: =IF(E15>0,E15/E13,"") | F14: =IF(F15>0,F15/F13,"") | G14: =IF(G15>0,G15/G13,"") | H14: =IF(H15>0,H15/H13,"") | I14: =IF(I15>0,I15/I13,"") | ... K14: =IF(K15>0,K15/K13,"") -> 24.107172 | L14: =IF(L13>0,L15/L13,0) -> #REF! | M14: =M25 -> #REF! | N14: =N25 -> #REF!
A15: Price | B15: ='Data Sheet'!B90 -> 0 | C15: ='Data Sheet'!C90 -> 0 | D15: ='Data Sheet'!D90 -> 0 | E15: ='Data Sheet'!E90 -> 0 | F15: ='Data Sheet'!F90 -> 0 | G15: ='Data Sheet'!G90 -> 0 | H15: ='Data Sheet'!H90 -> 0 | I15: ='Data Sheet'!I90 -> 0 | ... K15: ='Data Sheet'!K90 -> 3109.8 | L15: ='Data Sheet'!B8 -> 2994.4 | M15: =M13*M14 -> #REF! | N15: =N13*N14 -> #REF!
A17: RATIOS:
A18: Dividend Payout | B18: =IF('Data Sheet'!B30>0, 'Data Sheet'!B31/'Data Sheet'!B30, 0) -> 0 | C18: =IF('Data Sheet'!C30>0, 'Data Sheet'!C31/'Data Sheet'!C30, 0) -> 0 | D18: =IF('Data Sheet'!D30>0, 'Data Sheet'!D31/'Data Sheet'!D30, 0) -> 0 | E18: =IF('Data Sheet'!E30>0, 'Data Sheet'!E31/'Data Sheet'!E30, 0) -> 0 | F18: =IF('Data Sheet'!F30>0, 'Data Sheet'!F31/'Data Sheet'!F30, 0) -> 0 | G18: =IF('Data Sheet'!G30>0, 'Data Sheet'!G31/'Data Sheet'!G30, 0) -> 0 | H18: =IF('Data Sheet'!H30>0, 'Data Sheet'!H31/'Data Sheet'!H30, 0) -> 0 | I18: =IF('Data Sheet'!I30>0, 'Data Sheet'!I31/'Data Sheet'!I30, 0) -> 0 | ... K18: =IF('Data Sheet'!K30>0, 'Data Sheet'!K31/'Data Sheet'!K30, 0) -> 0.015501307
A19: OPM | B19: =IF(B6>0,B6/B4,0) -> 0 | C19: =IF(C6>0,C6/C4,0) -> 0 | D19: =IF(D6>0,D6/D4,0) -> 0 | E19: =IF(E6>0,E6/E4,0) -> 0.046483079 | F19: =IF(F6>0,F6/F4,0) -> 0.043440633 | G19: =IF(G6>0,G6/G4,0) -> 0.037119824 | H19: =IF(H6>0,H6/H4,0) -> 0.12380775 | I19: =IF(I6>0,I6/I4,0) -> 0.13813686 | ... L19: =IF(L6>0,L6/L4,0) -> 0.22265822
G22: TRENDS: | H22: 10 YEARS | I22: 7 YEARS | J22: 5 YEARS | K22: 3 YEARS | L22: RECENT | M22: BEST | N22: WORST
G23: Sales Growth | H23: =IF(B4=0,"",POWER($K4/B4,1/9)-1) | I23: =IF(D4=0,"",POWER($K4/D4,1/7)-1) | J23: =IF(F4=0,"",POWER($K4/F4,1/5)-1) -> 0.68515149 | K23: =IF(H4=0,"",POWER($K4/H4, 1/3)-1) -> 0.57820266 | L23: =IF(ISERROR(MAX(IF(J4=0,"",(K4-J4)/J4),IF(K4=0,"",(L4-K4)/K4))),"",MAX(IF(J4=0,"",(K4-J4)/J4),IF(K4=0,"",(L4-K4)/K4))) -> 0.83715393 | M23: =MAX(K23:L23) -> 0.83715393 | N23: =MIN(H23:L23) -> 0.57820266
G24: OPM | H24: =IF(SUM(B4:$K$4)=0,"",SUMPRODUCT(B19:$K$19,B4:$K$4)/SUM(B4:$K$4)) -> 0.17175227 | I24: =IF(SUM(E4:$K$4)=0,"",SUMPRODUCT(E19:$K$19,E4:$K$4)/SUM(E4:$K$4)) -> 0.17175227 | J24: =IF(SUM(G4:$K$4)=0,"",SUMPRODUCT(G19:$K$19,G4:$K$4)/SUM(G4:$K$4)) -> 0.17982812 | K24: =IF(SUM(I4:$K$4)=0, "", SUMPRODUCT(I19:$K$19,I4:$K$4)/SUM(I4:$K$4)) -> 0.1948249 | L24: =L19 -> 0.22265822 | M24: =MAX(K24:L24) -> 0.22265822 | N24: =MIN(H24:L24) -> 0.17175227
G25: Price to Earning | H25: =IF(ISERROR(AVERAGEIF(B14:$L14,">0")),"",AVERAGEIF(B14:$L14,">0")) -> 30.551488 | I25: =IF(ISERROR(AVERAGEIF(E14:$L14,">0")),"",AVERAGEIF(E14:$L14,">0")) -> 30.551488 | J25: =IF(ISERROR(AVERAGEIF(G14:$L14,">0")),"",AVERAGEIF(G14:$L14,">0")) -> 30.551488 | K25: =IF(ISERROR(AVERAGEIF(I14:$L14,">0")),"",AVERAGEIF(I14:$L14,">0")) -> 30.551488 | L25: =L14 -> #REF! | M25: =MAX(K25:L25) -> #REF! | N25: =MIN(H25:L25) -> #REF!

Sheet Financials

Sheet HistoricalFS
B2: ="Historical Financial Statement - "&UPDATE -> Historical Financial Statement - WAAREE ENERGIES LTD
B3: Years | C3: ='Data Sheet'!E16 -> 43921 | D3: ='Data Sheet'!F16 -> 44286 | E3: ='Data Sheet'!G16 -> 44651 | F3: ='Data Sheet'!H16 -> 45016 | G3: ='Data Sheet'!I16 -> 45382 | H3: ='Data Sheet'!J16 -> 45747 | I3: ='Data Sheet'!K16 -> 46112 | J3: LTM
A5: # | B5: Income Statement
B6: Sales | C6: =IFERROR('Data Sheet'!E17,0) -> 1995.78 | D6: =IFERROR('Data Sheet'!F17,0) -> 1952.78 | E6: =IFERROR('Data Sheet'!G17,0) -> 2854.27 | F6: =IFERROR('Data Sheet'!H17,0) -> 6750.87 | G6: =IFERROR('Data Sheet'!I17,0) -> 11397.61 | H6: =IFERROR('Data Sheet'!J17,0) -> 14444.5 | I6: =IFERROR('Data Sheet'!K17,0) -> 26536.77 | J6: =IFERROR(SUM('Data Sheet'!H42:K42),0) -> 26536.77
B7: Sales Growth | D7: =IFERROR(D6/C6-1,0) -> -0.021545461 | E7: =IFERROR(E6/D6-1,0) -> 0.46164442 | F7: =IFERROR(F6/E6-1,0) -> 1.3651827 | G7: =IFERROR(G6/F6-1,0) -> 0.68831721 | H7: =IFERROR(H6/G6-1,0) -> 0.2673271 | I7: =IFERROR(I6/H6-1,0) -> 0.83715393 | J7: =IFERROR(J6/I6-1,0) -> 0
B9: COGS | C9: =IFERROR(SUM('Data Sheet'!E18,'Data Sheet'!E20:E22)-1*'Data Sheet'!E19,0) -> 1831.48 | D9: =IFERROR(SUM('Data Sheet'!F18,'Data Sheet'!F20:F22)-1*'Data Sheet'!F19,0) -> 1808.55 | E9: =IFERROR(SUM('Data Sheet'!G18,'Data Sheet'!G20:G22)-1*'Data Sheet'!G19,0) -> 2666.06 | F9: =IFERROR(SUM('Data Sheet'!H18,'Data Sheet'!H20:H22)-1*'Data Sheet'!H19,0) -> 5737.92 | G9: =IFERROR(SUM('Data Sheet'!I18,'Data Sheet'!I20:I22)-1*'Data Sheet'!I19,0) -> 9192.6 | H9: =IFERROR(SUM('Data Sheet'!J18,'Data Sheet'!J20:J22)-1*'Data Sheet'!J19,0) -> 10843.08 | I9: =IFERROR(SUM('Data Sheet'!K18,'Data Sheet'!K20:K22)-1*'Data Sheet'!K19,0) -> 18680.19 | J9: =IFERROR(SUM('Data Sheet'!H43:K43),0) -> 20628.14
B10: COGS % Sales | C10: =IFERROR(C9/#REF!-1,0) -> 0 | D10: =IFERROR(D9/C9-1,0) -> -0.012519929 | E10: =IFERROR(E9/D9-1,0) -> 0.47414227 | F10: =IFERROR(F9/E9-1,0) -> 1.1522096 | G10: =IFERROR(G9/F9-1,0) -> 0.6020788 | H10: =IFERROR(H9/G9-1,0) -> 0.17954442 | I10: =IFERROR(I9/H9-1,0) -> 0.72277526 | J10: =IFERROR(J9/I9-1,0) -> 0.10427892
B12: Gross Profit | C12: =C6-C9 -> 164.3 | D12: =D6-D9 -> 144.23 | E12: =E6-E9 -> 188.21 | F12: =F6-F9 -> 1012.95 | G12: =G6-G9 -> 2205.01 | H12: =H6-H9 -> 3601.42 | I12: =I6-I9 -> 7856.58 | J12: =J6-J9 -> 5908.63
B13: Gross Margin | C13: =IFERROR(C12/#REF!-1,0) -> 0 | D13: =IFERROR(D12/C12-1,0) -> -0.1221546 | E13: =IFERROR(E12/D12-1,0) -> 0.30492963 | F13: =IFERROR(F12/E12-1,0) -> 4.3820201 | G13: =IFERROR(G12/F12-1,0) -> 1.1768202 | H13: =IFERROR(H12/G12-1,0) -> 0.63328964 | I13: =IFERROR(I12/H12-1,0) -> 1.1815228 | J13: =IFERROR(J12/I12-1,0) -> -0.24793867
B15: Selling & Gen Exp | C15: =IFERROR(SUM('Data Sheet'!E23:E24),0) -> 71.53 | D15: =IFERROR(SUM('Data Sheet'!F23:F24),0) -> 59.4 | E15: =IFERROR(SUM('Data Sheet'!G23:G24),0) -> 82.26 | F15: =IFERROR(SUM('Data Sheet'!H23:H24),0) -> 177.14 | G15: =IFERROR(SUM('Data Sheet'!I23:I24),0) -> 630.58 | H15: =IFERROR(SUM('Data Sheet'!J23:J24),0) -> 879.78 | I15: =IFERROR(SUM('Data Sheet'!K23:K24),0) -> 1947.94 | J15: 0
B16: S&G Exp % Sales | C16: =IFERROR(C15/#REF!-1,0) -> 0 | D16: =IFERROR(D15/C15-1,0) -> -0.1695792 | E16: =IFERROR(E15/D15-1,0) -> 0.38484848 | F16: =IFERROR(F15/E15-1,0) -> 1.153416 | G16: =IFERROR(G15/F15-1,0) -> 2.5597832 | H16: =IFERROR(H15/G15-1,0) -> 0.39519173 | I16: =IFERROR(I15/H15-1,0) -> 1.2141217 | J16: =IFERROR(J15/I15-1,0) -> -1
B18: EBITDA | C18: =C12-C15 -> 92.77 | D18: =D12-D15 -> 84.83 | E18: =E12-E15 -> 105.95 | F18: =F12-F15 -> 835.81 | G18: =G12-G15 -> 1574.43 | H18: =H12-H15 -> 2721.64 | I18: =I12-I15 -> 5908.64 | J18: =J12-J15 -> 5908.63
B19: EBITDA Margins | C19: =IFERROR(C18/#REF!-1,0) -> 0 | D19: =IFERROR(D18/C18-1,0) -> -0.085588013 | E19: =IFERROR(E18/D18-1,0) -> 0.24896853 | F19: =IFERROR(F18/E18-1,0) -> 6.8887211 | G19: =IFERROR(G18/F18-1,0) -> 0.88371759 | H19: =IFERROR(H18/G18-1,0) -> 0.728651 | I19: =IFERROR(I18/H18-1,0) -> 1.1709851 | J19: =IFERROR(J18/I18-1,0) -> -1.6924368e-06
B21: Other income | C21: =IFERROR('Data Sheet'!E25,0) -> 25.01 | D21: =IFERROR('Data Sheet'!F25,0) -> 44.65 | E21: =IFERROR('Data Sheet'!G25,0) -> 96.58 | F21: =IFERROR('Data Sheet'!H25,0) -> 87.74 | G21: =IFERROR('Data Sheet'!I25,0) -> 576.49 | H21: =IFERROR('Data Sheet'!J25,0) -> 397.54 | I21: =IFERROR('Data Sheet'!K25,0) -> 413.37 | J21: =IFERROR('Data Sheet'!L25,0) -> 0
B23: Interest | C23: =IFERROR('Data Sheet'!E27,0) -> 33.71 | D23: =IFERROR('Data Sheet'!F27,0) -> 30.92 | E23: =IFERROR('Data Sheet'!G27,0) -> 40.88 | F23: =IFERROR('Data Sheet'!H27,0) -> 82.27 | G23: =IFERROR('Data Sheet'!I27,0) -> 139.91 | H23: =IFERROR('Data Sheet'!J27,0) -> 152.09 | I23: =IFERROR('Data Sheet'!K27,0) -> 280.5 | J23: =IFERROR(SUM('Data Sheet'!H46:K46),0) -> 280.5
B24: Interest % Sales | C24: =IFERROR(C23/#REF!-1,0) -> 0 | D24: =IFERROR(D23/C23-1,0) -> -0.082764758 | E24: =IFERROR(E23/D23-1,0) -> 0.3221216 | F24: =IFERROR(F23/E23-1,0) -> 1.0124755 | G24: =IFERROR(G23/F23-1,0) -> 0.70061991 | H24: =IFERROR(H23/G23-1,0) -> 0.087055965 | I24: =IFERROR(I23/H23-1,0) -> 0.84430272 | J24: =IFERROR(J23/I23-1,0) -> 0
M25: Other Income | N25: =IFERROR('Data Sheet'!B25,0) -> 0 | O25: =IFERROR('Data Sheet'!C25,0) -> 0 | P25: =IFERROR('Data Sheet'!D25,0) -> 0 | Q25: =IFERROR('Data Sheet'!E25,0) -> 25.01 | R25: =IFERROR('Data Sheet'!F25,0) -> 44.65 | S25: =IFERROR('Data Sheet'!G25,0) -> 96.58 | T25: =IFERROR('Data Sheet'!H25,0) -> 87.74 | U25: =IFERROR('Data Sheet'!I25,0) -> 576.49 | ... W25: =IFERROR('Data Sheet'!K25,0) -> 413.37 | X25: =IFERROR(SUM('Data Sheet'!H44:K44),0) -> 413.38
B26: Depreciation | C26: =IFERROR('Data Sheet'!E26,0) -> 27.13 | D26: =IFERROR('Data Sheet'!F26,0) -> 28.66 | E26: =IFERROR('Data Sheet'!G26,0) -> 43.27 | F26: =IFERROR('Data Sheet'!H26,0) -> 164.13 | G26: =IFERROR('Data Sheet'!I26,0) -> 276.81 | H26: =IFERROR('Data Sheet'!J26,0) -> 402.45 | I26: =IFERROR('Data Sheet'!K26,0) -> 989.72 | J26: 0
B27: Depreciation % Sales | C27: =IFERROR(C26/#REF!-1,0) -> 0 | D27: =IFERROR(D26/C26-1,0) -> 0.056395135 | E27: =IFERROR(E26/D26-1,0) -> 0.50976971 | F27: =IFERROR(F26/E26-1,0) -> 2.7931592 | G27: =IFERROR(G26/F26-1,0) -> 0.68652897 | H27: =IFERROR(H26/G26-1,0) -> 0.45388534 | I27: =IFERROR(I26/H26-1,0) -> 1.4592372 | J27: =IFERROR(J26/I26-1,0) -> -1
B29: EBIT | C29: =C18-C26 -> 65.64 | D29: =D18-D26 -> 56.17 | E29: =E18-E26 -> 62.68 | F29: =F18-F26 -> 671.68 | G29: =G18-G26 -> 1297.62 | H29: =H18-H26 -> 2319.19 | I29: =I18-I26 -> 4918.92 | J29: =J18-J26 -> 5908.63
B30: EBIT % Sales | C30: =IFERROR(C29/#REF!-1,0) -> 0 | D30: =IFERROR(D29/C29-1,0) -> -0.14427179 | E30: =IFERROR(E29/D29-1,0) -> 0.11589817 | F30: =IFERROR(F29/E29-1,0) -> 9.7160179 | G30: =IFERROR(G29/F29-1,0) -> 0.9319021 | H30: =IFERROR(H29/G29-1,0) -> 0.78726438 | I30: =IFERROR(I29/H29-1,0) -> 1.1209646 | J30: =IFERROR(J29/I29-1,0) -> 0.20120474
B32: Earnings Before Tax | C32: =C18-C23-C26+C21 -> 56.94 | D32: =D18-D23-D26+D21 -> 69.9 | E32: =E18-E23-E26+E21 -> 118.38 | F32: =F18-F23-F26+F21 -> 677.15 | G32: =G18-G23-G26+G21 -> 1734.2 | H32: =H18-H23-H26+H21 -> 2564.64 | I32: =I18-I23-I26+I21 -> 5051.79 | J32: =J18-J23-J26+J21 -> 5628.13
B33: EBT % Sales | C33: =IFERROR(C32/#REF!-1,0) -> 0 | D33: =IFERROR(D32/C32-1,0) -> 0.22760801 | E33: =IFERROR(E32/D32-1,0) -> 0.69356223 | F33: =IFERROR(F32/E32-1,0) -> 4.7201385 | G33: =IFERROR(G32/F32-1,0) -> 1.5610278 | H33: =IFERROR(H32/G32-1,0) -> 0.47886057 | I33: =IFERROR(I32/H32-1,0) -> 0.96978523 | J33: =IFERROR(J32/I32-1,0) -> 0.11408629
B35: Tax | C35: =IFERROR('Data Sheet'!E29,0) -> 17.92 | D35: =IFERROR('Data Sheet'!F29,0) -> 21.72 | E35: =IFERROR('Data Sheet'!G29,0) -> 38.72 | F35: =IFERROR('Data Sheet'!H29,0) -> 176.88 | G35: =IFERROR('Data Sheet'!I29,0) -> 459.82 | H35: =IFERROR('Data Sheet'!J29,0) -> 636.51 | I35: =IFERROR('Data Sheet'!K29,0) -> 1167.64 | J35: =IFERROR(SUM('Data Sheet'!H48:K48),0) -> 1167.64
B36: Effective Tax Rate | C36: =IFERROR(C35/#REF!-1,0) -> 0 | D36: =IFERROR(D35/C35-1,0) -> 0.21205357 | E36: =IFERROR(E35/D35-1,0) -> 0.78268877 | F36: =IFERROR(F35/E35-1,0) -> 3.5681818 | G36: =IFERROR(G35/F35-1,0) -> 1.5996156 | H36: =IFERROR(H35/G35-1,0) -> 0.38425906 | I36: =IFERROR(I35/H35-1,0) -> 0.83444094 | J36: =IFERROR(J35/I35-1,0) -> 0
B38: Net Profit | C38: =C32-C35 -> 39.02 | D38: =D32-D35 -> 48.18 | E38: =E32-E35 -> 79.66 | F38: =F32-F35 -> 500.27 | G38: =G32-G35 -> 1274.38 | H38: =H32-H35 -> 1928.13 | I38: =I32-I35 -> 3884.15 | J38: =J32-J35 -> 4460.49
B39: Net Margin | C39: =IFERROR(C38/#REF!-1,0) -> 0 | D39: =IFERROR(D38/C38-1,0) -> 0.23475141 | E39: =IFERROR(E38/D38-1,0) -> 0.65338315 | F39: =IFERROR(F38/E38-1,0) -> 5.2800653 | G39: =IFERROR(G38/F38-1,0) -> 1.5473844 | H39: =IFERROR(H38/G38-1,0) -> 0.51299455 | I39: =IFERROR(I38/H38-1,0) -> 1.0144648 | J39: =IFERROR(J38/I38-1,0) -> 0.14838253
B41: No. of Equity Shares | C41: =IFERROR('Data Sheet'!E93,0) -> 19.71 | D41: =IFERROR('Data Sheet'!F93,0) -> 19.71 | E41: =IFERROR('Data Sheet'!G93,0) -> 19.71 | F41: =IFERROR('Data Sheet'!H93,0) -> 19.71 | G41: =IFERROR('Data Sheet'!I93,0) -> 19.71 | H41: =IFERROR('Data Sheet'!J93,0) -> 28.73 | I41: =IFERROR('Data Sheet'!K93,0) -> 28.77 | J41: =IFERROR('Data Sheet'!K93,0) -> 28.77
B43: EPS | C43: =IFERROR(C38/C41,0) -> 1.9797057 | D43: =IFERROR(D38/D41,0) -> 2.4444444 | E43: =IFERROR(E38/E41,0) -> 4.0416032 | F43: =IFERROR(F38/F41,0) -> 25.381532 | G43: =IFERROR(G38/G41,0) -> 64.65652 | H43: =IFERROR(H38/H41,0) -> 67.112078 | I43: =IFERROR(I38/I41,0) -> 135.00695 | J43: =IFERROR(J38/J41,0) -> 155.03962
B44: EPS Growth % | C44: =IFERROR(C43/#REF!-1,0) -> 0 | D44: =IFERROR(D43/C43-1,0) -> 0.23475141 | E44: =IFERROR(E43/D43-1,0) -> 0.65338315 | F44: =IFERROR(F43/E43-1,0) -> 5.2800653 | G44: =IFERROR(G43/F43-1,0) -> 1.5473844 | H44: =IFERROR(H43/G43-1,0) -> 0.037978512 | I44: =IFERROR(I43/H43-1,0) -> 1.011664 | J44: =IFERROR(J43/I43-1,0) -> 0.14838253
B46: Divident per share | C46: =-IFERROR('Data Sheet'!E31/C41,0) -> 0 | D46: =-IFERROR('Data Sheet'!F31/D41,0) -> 0 | E46: =-IFERROR('Data Sheet'!G31/E41,0) -> 0 | F46: =-IFERROR('Data Sheet'!H31/F41,0) -> 0 | G46: =-IFERROR('Data Sheet'!I31/G41,0) -> 0 | H46: =-IFERROR('Data Sheet'!J31/H41,0) -> 0 | I46: =-IFERROR('Data Sheet'!K31/I41,0) -> -1.9996524 | J46: =-IFERROR('Data Sheet'!L31/J41,0) -> 0
B47: Dividend Payout ratio | C47: =IFERROR(C46/C43,0) -> 0 | D47: =IFERROR(D46/D43,0) -> 0 | E47: =IFERROR(E46/E43,0) -> 0 | F47: =IFERROR(F46/F43,0) -> 0 | G47: =IFERROR(G46/G43,0) -> 0 | H47: =IFERROR(H46/H43,0) -> 0 | I47: =IFERROR(I46/I43,0) -> -0.014811477 | J47: =IFERROR(J46/J43,0) -> 0
B49: Retained Earnings | C49: =IFERROR(IF(C43>C46,1-C47,0),0) -> 1 | D49: =IFERROR(IF(D43>D46,1-D47,0),0) -> 1 | E49: =IFERROR(IF(E43>E46,1-E47,0),0) -> 1 | F49: =IFERROR(IF(F43>F46,1-F47,0),0) -> 1 | G49: =IFERROR(IF(G43>G46,1-G47,0),0) -> 1 | H49: =IFERROR(IF(H43>H46,1-H47,0),0) -> 1 | I49: =IFERROR(IF(I43>I46,1-I47,0),0) -> 1.0148115 | J49: =IFERROR(IF(J43>J46,1-J47,0),0) -> 1
A51: # | B51: Balance sheet
B53: Equity Share Capital | C53: =IFERROR('Data Sheet'!E57,0) -> 197.14 | D53: =IFERROR('Data Sheet'!F57,0) -> 197.14 | E53: =IFERROR('Data Sheet'!G57,0) -> 197.14 | F53: =IFERROR('Data Sheet'!H57,0) -> 243.37 | G53: =IFERROR('Data Sheet'!I57,0) -> 262.96 | H53: =IFERROR('Data Sheet'!J57,0) -> 287.28 | I53: =IFERROR('Data Sheet'!K57,0) -> 287.65
B54: Reserves | C54: =IFERROR('Data Sheet'!E58,0) -> 100.88 | D54: =IFERROR('Data Sheet'!F58,0) -> 147.85 | E54: =IFERROR('Data Sheet'!G58,0) -> 230.51 | F54: =IFERROR('Data Sheet'!H58,0) -> 1595.04 | G54: =IFERROR('Data Sheet'!I58,0) -> 3824.85 | H54: =IFERROR('Data Sheet'!J58,0) -> 9191.92 | I54: =IFERROR('Data Sheet'!K58,0) -> 14149.69
B55: Borrowings | C55: =IFERROR('Data Sheet'!E59,0) -> 157.07 | D55: =IFERROR('Data Sheet'!F59,0) -> 339.9 | E55: =IFERROR('Data Sheet'!G59,0) -> 363.41 | F55: =IFERROR('Data Sheet'!H59,0) -> 320.27 | G55: =IFERROR('Data Sheet'!I59,0) -> 553.39 | H55: =IFERROR('Data Sheet'!J59,0) -> 1198.99 | I55: =IFERROR('Data Sheet'!K59,0) -> 3212.62
B56: Other Liabilities | C56: =IFERROR('Data Sheet'!E60,0) -> 483.18 | D56: =IFERROR('Data Sheet'!F60,0) -> 595.64 | E56: =IFERROR('Data Sheet'!G60,0) -> 1362.49 | F56: =IFERROR('Data Sheet'!H60,0) -> 5246.97 | G56: =IFERROR('Data Sheet'!I60,0) -> 6635.44 | H56: =IFERROR('Data Sheet'!J60,0) -> 9027.85 | I56: =IFERROR('Data Sheet'!K60,0) -> 12465.41
B57: Total Liabilities | C57: =IFERROR('Data Sheet'!E61,0) -> 938.27 | D57: =IFERROR('Data Sheet'!F61,0) -> 1280.53 | E57: =IFERROR('Data Sheet'!G61,0) -> 2153.55 | F57: =IFERROR('Data Sheet'!H61,0) -> 7405.65 | G57: =IFERROR('Data Sheet'!I61,0) -> 11276.64 | H57: =IFERROR('Data Sheet'!J61,0) -> 19706.04 | I57: =IFERROR('Data Sheet'!K61,0) -> 30115.37
B59: Fixed Assets Net Block | C59: =IFERROR('Data Sheet'!E62,0) -> 151.75 | D59: =IFERROR('Data Sheet'!F62,0) -> 284.71 | E59: =IFERROR('Data Sheet'!G62,0) -> 624.62 | F59: =IFERROR('Data Sheet'!H62,0) -> 1105.27 | G59: =IFERROR('Data Sheet'!I62,0) -> 1449.85 | H59: =IFERROR('Data Sheet'!J62,0) -> 4050.95 | I59: =IFERROR('Data Sheet'!K62,0) -> 7328.57
...

Sheet Ratio Analysis
B2: ="Ratio Analysis - "&UPDATE -> Ratio Analysis - WAAREE ENERGIES LTD
B3: Years | C3: ='Data Sheet'!E16 -> 43921 | D3: ='Data Sheet'!F16 -> 44286 | E3: ='Data Sheet'!G16 -> 44651 | F3: ='Data Sheet'!H16 -> 45016 | G3: ='Data Sheet'!I16 -> 45382 | H3: ='Data Sheet'!J16 -> 45747 | I3: ='Data Sheet'!K16 -> 46112 | J3: Trend | K3: Mean | L3: Median
B5: SalesGrowth | C5: =IFERROR(HistoricalFS!C7,0) -> 0 | D5: =IFERROR(HistoricalFS!D7,0) -> -0.021545461 | E5: =IFERROR(HistoricalFS!E7,0) -> 0.46164442 | F5: =IFERROR(HistoricalFS!F7,0) -> 1.3651827 | G5: =IFERROR(HistoricalFS!G7,0) -> 0.68831721 | H5: =IFERROR(HistoricalFS!H7,0) -> 0.2673271 | I5: =IFERROR(HistoricalFS!I7,0) -> 0.83715393 | K5: =IFERROR(AVERAGE(C5:I5),0) -> 0.51401141 | L5: =IFERROR(MEDIAN(C5:I5),0) -> 0.46164442
B6: EBITDA Growth | C6: =IFERROR(HistoricalFS!C19,0) -> 0 | D6: =IFERROR(HistoricalFS!D18/HistoricalFS!C18-1,0) -> -0.085588013 | E6: =IFERROR(HistoricalFS!E18/HistoricalFS!D18-1,0) -> 0.24896853 | F6: =IFERROR(HistoricalFS!F18/HistoricalFS!E18-1,0) -> 6.8887211 | G6: =IFERROR(HistoricalFS!G18/HistoricalFS!F18-1,0) -> 0.88371759 | H6: =IFERROR(HistoricalFS!H18/HistoricalFS!G18-1,0) -> 0.728651 | I6: =IFERROR(HistoricalFS!I18/HistoricalFS!H18-1,0) -> 1.1709851 | K6: =IFERROR(AVERAGE(C6:I6),0) -> 1.405065 | L6: =IFERROR(MEDIAN(C6:I6),0) -> 0.728651
B7: EBIT Growth | C7: =IFERROR(HistoricalFS!C30,0) -> 0 | D7: =IFERROR(HistoricalFS!D32/HistoricalFS!C32-1,0) -> 0.22760801 | E7: =IFERROR(HistoricalFS!E32/HistoricalFS!D32-1,0) -> 0.69356223 | F7: =IFERROR(HistoricalFS!F32/HistoricalFS!E32-1,0) -> 4.7201385 | G7: =IFERROR(HistoricalFS!G32/HistoricalFS!F32-1,0) -> 1.5610278 | H7: =IFERROR(HistoricalFS!H32/HistoricalFS!G32-1,0) -> 0.47886057 | I7: =IFERROR(HistoricalFS!I32/HistoricalFS!H32-1,0) -> 0.96978523 | K7: =IFERROR(AVERAGE(C7:I7),0) -> 1.2358546 | L7: =IFERROR(MEDIAN(C7:I7),0) -> 0.69356223
B8: NetProfit Growth | C8: =IFERROR(HistoricalFS!C39,0) -> 0 | D8: =IFERROR(HistoricalFS!D38/HistoricalFS!C38-1,0) -> 0.23475141 | E8: =IFERROR(HistoricalFS!E38/HistoricalFS!D38-1,0) -> 0.65338315 | F8: =IFERROR(HistoricalFS!F38/HistoricalFS!E38-1,0) -> 5.2800653 | G8: =IFERROR(HistoricalFS!G38/HistoricalFS!F38-1,0) -> 1.5473844 | H8: =IFERROR(HistoricalFS!H38/HistoricalFS!G38-1,0) -> 0.51299455 | I8: =IFERROR(HistoricalFS!I38/HistoricalFS!H38-1,0) -> 1.0144648 | K8: =IFERROR(AVERAGE(C8:I8),0) -> 1.3204348 | L8: =IFERROR(MEDIAN(C8:I8),0) -> 0.65338315
B9: Dividend Growth | C9: =IFERROR(HistoricalFS!C47,0) -> 0 | D9: =IFERROR(HistoricalFS!D46/HistoricalFS!C46-1,0) -> 0 | E9: =IFERROR(HistoricalFS!E46/HistoricalFS!D46-1,0) -> 0 | F9: =IFERROR(HistoricalFS!F46/HistoricalFS!E46-1,0) -> 0 | G9: =IFERROR(HistoricalFS!G46/HistoricalFS!F46-1,0) -> 0 | H9: =IFERROR(HistoricalFS!H46/HistoricalFS!G46-1,0) -> 0 | I9: =IFERROR(HistoricalFS!I46/HistoricalFS!H46-1,0) -> 0 | K9: =IFERROR(AVERAGE(C9:I9),0) -> 0 | L9: =IFERROR(MEDIAN(C9:I9),0) -> 0
B11: Gross Margin | C11: =IFERROR(HistoricalFS!C13,0) -> 0 | D11: =IFERROR(HistoricalFS!D13,0) -> -0.1221546 | E11: =IFERROR(HistoricalFS!E13,0) -> 0.30492963 | F11: =IFERROR(HistoricalFS!F13,0) -> 4.3820201 | G11: =IFERROR(HistoricalFS!G13,0) -> 1.1768202 | H11: =IFERROR(HistoricalFS!H13,0) -> 0.63328964 | I11: =IFERROR(HistoricalFS!I13,0) -> 1.1815228 | K11: =IFERROR(AVERAGE(C11:I11),0) -> 1.0794897 | L11: =IFERROR(MEDIAN(C11:I11),0) -> 0.63328964
B12: EBITDA Margin | C12: =IFERROR(HistoricalFS!C19,0) -> 0 | D12: =IFERROR(HistoricalFS!D19,0) -> -0.085588013 | E12: =IFERROR(HistoricalFS!E19,0) -> 0.24896853 | F12: =IFERROR(HistoricalFS!F19,0) -> 6.8887211 | G12: =IFERROR(HistoricalFS!G19,0) -> 0.88371759 | H12: =IFERROR(HistoricalFS!H19,0) -> 0.728651 | I12: =IFERROR(HistoricalFS!I19,0) -> 1.1709851 | K12: =IFERROR(AVERAGE(C12:I12),0) -> 1.405065 | L12: =IFERROR(MEDIAN(C12:I12),0) -> 0.728651
B13: EBIT Margin | C13: =IFERROR((HistoricalFS!C18-HistoricalFS!C26)/HistoricalFS!C6,0) -> 0.032889397 | D13: =IFERROR((HistoricalFS!D18-HistoricalFS!D26)/HistoricalFS!D6,0) -> 0.028764121 | E13: =IFERROR((HistoricalFS!E18-HistoricalFS!E26)/HistoricalFS!E6,0) -> 0.021960081 | F13: =IFERROR((HistoricalFS!F18-HistoricalFS!F26)/HistoricalFS!F6,0) -> 0.099495324 | G13: =IFERROR((HistoricalFS!G18-HistoricalFS!G26)/HistoricalFS!G6,0) -> 0.11385018 | H13: =IFERROR((HistoricalFS!H18-HistoricalFS!H26)/HistoricalFS!H6,0) -> 0.16055869 | I13: =IFERROR((HistoricalFS!I18-HistoricalFS!I26)/HistoricalFS!I6,0) -> 0.18536242 | K13: =IFERROR(AVERAGE(C13:I13),0) -> 0.091840032 | L13: =IFERROR(MEDIAN(C13:I13),0) -> 0.099495324
B14: EBT Margin | C14: =IFERROR(HistoricalFS!C33,0) -> 0 | D14: =IFERROR(HistoricalFS!D33,0) -> 0.22760801 | E14: =IFERROR(HistoricalFS!E33,0) -> 0.69356223 | F14: =IFERROR(HistoricalFS!F33,0) -> 4.7201385 | G14: =IFERROR(HistoricalFS!G33,0) -> 1.5610278 | H14: =IFERROR(HistoricalFS!H33,0) -> 0.47886057 | I14: =IFERROR(HistoricalFS!I33,0) -> 0.96978523 | K14: =IFERROR(AVERAGE(C14:I14),0) -> 1.2358546 | L14: =IFERROR(MEDIAN(C14:I14),0) -> 0.69356223
B15: Net Profit Margin | C15: =IFERROR(HistoricalFS!C39,0) -> 0 | D15: =IFERROR(HistoricalFS!D39,0) -> 0.23475141 | E15: =IFERROR(HistoricalFS!E39,0) -> 0.65338315 | F15: =IFERROR(HistoricalFS!F39,0) -> 5.2800653 | G15: =IFERROR(HistoricalFS!G39,0) -> 1.5473844 | H15: =IFERROR(HistoricalFS!H39,0) -> 0.51299455 | I15: =IFERROR(HistoricalFS!I39,0) -> 1.0144648 | K15: =IFERROR(AVERAGE(C15:I15),0) -> 1.3204348 | L15: =IFERROR(MEDIAN(C15:I15),0) -> 0.65338315
B17: SalesExp% Sales | C17: =IFERROR(HistoricalFS!C16,0) -> 0 | D17: =IFERROR(HistoricalFS!D16,0) -> -0.1695792 | E17: =IFERROR(HistoricalFS!E16,0) -> 0.38484848 | F17: =IFERROR(HistoricalFS!F16,0) -> 1.153416 | G17: =IFERROR(HistoricalFS!G16,0) -> 2.5597832 | H17: =IFERROR(HistoricalFS!H16,0) -> 0.39519173 | I17: =IFERROR(HistoricalFS!I16,0) -> 1.2141217 | K17: =IFERROR(AVERAGE(C17:I17),0) -> 0.79111171 | L17: =IFERROR(MEDIAN(C17:I17),0) -> 0.39519173
B18: Deprn%Sales | C18: =IFERROR(HistoricalFS!C27,0) -> 0 | D18: =IFERROR(HistoricalFS!D27,0) -> 0.056395135 | E18: =IFERROR(HistoricalFS!E27,0) -> 0.50976971 | F18: =IFERROR(HistoricalFS!F27,0) -> 2.7931592 | G18: =IFERROR(HistoricalFS!G27,0) -> 0.68652897 | H18: =IFERROR(HistoricalFS!H27,0) -> 0.45388534 | I18: =IFERROR(HistoricalFS!I27,0) -> 1.4592372 | K18: =IFERROR(AVERAGE(C18:I18),0) -> 0.85128222 | L18: =IFERROR(MEDIAN(C18:I18),0) -> 0.50976971
B19: OprIncome%Sales | C19: =C13 -> 0.032889397 | D19: =D13 -> 0.028764121 | E19: =E13 -> 0.021960081 | F19: =F13 -> 0.099495324 | G19: =G13 -> 0.11385018 | H19: =H13 -> 0.16055869 | I19: =I13 -> 0.18536242 | K19: =IFERROR(AVERAGE(C19:I19),0) -> 0.091840032 | L19: =IFERROR(MEDIAN(C19:I19),0) -> 0.099495324
B21: Return on Cap Emp | C21: =IFERROR((HistoricalFS!C29)/(SUM(HistoricalFS!C53:C55)),0) -> 0.14423521 | D21: =IFERROR((HistoricalFS!D29)/(SUM(HistoricalFS!D53:D55)),0) -> 0.08201317 | E21: =IFERROR((HistoricalFS!E29)/(SUM(HistoricalFS!E53:E55)),0) -> 0.079235456 | F21: =IFERROR((HistoricalFS!F29)/(SUM(HistoricalFS!F53:F55)),0) -> 0.31115311 | G21: =IFERROR((HistoricalFS!G29)/(SUM(HistoricalFS!G53:G55)),0) -> 0.27958718 | H21: =IFERROR((HistoricalFS!H29)/(SUM(HistoricalFS!H53:H55)),0) -> 0.21718943 | I21: =IFERROR((HistoricalFS!I29)/(SUM(HistoricalFS!I53:I55)),0) -> 0.27869298 | K21: =IFERROR(AVERAGE(C21:I21),0) -> 0.19887236 | L21: =IFERROR(MEDIAN(C21:I21),0) -> 0.21718943
B22: Retained Earn % | C22: =IFERROR(HistoricalFS!C49,0) -> 1 | D22: =IFERROR(HistoricalFS!D49,0) -> 1 | E22: =IFERROR(HistoricalFS!E49,0) -> 1 | F22: =IFERROR(HistoricalFS!F49,0) -> 1 | G22: =IFERROR(HistoricalFS!G49,0) -> 1 | H22: =IFERROR(HistoricalFS!H49,0) -> 1 | I22: =IFERROR(HistoricalFS!I49,0) -> 1.0148115 | K22: =IFERROR(AVERAGE(C22:I22),0) -> 1.0021159 | L22: =IFERROR(MEDIAN(C22:I22),0) -> 1
B23: Return on Equity% | C23: =IFERROR(HistoricalFS!C38/SUM(HistoricalFS!C53:C54),0) -> 0.13093081 | D23: =IFERROR(HistoricalFS!D38/SUM(HistoricalFS!D53:D54),0) -> 0.13965622 | E23: =IFERROR(HistoricalFS!E38/SUM(HistoricalFS!E53:E54),0) -> 0.18627382 | F23: =IFERROR(HistoricalFS!F38/SUM(HistoricalFS!F53:F54),0) -> 0.27212102 | G23: =IFERROR(HistoricalFS!G38/SUM(HistoricalFS!G53:G54),0) -> 0.31175128 | H23: =IFERROR(HistoricalFS!H38/SUM(HistoricalFS!H53:H54),0) -> 0.20340641 | I23: =IFERROR(HistoricalFS!I38/SUM(HistoricalFS!I53:I54),0) -> 0.26903502 | K23: =IFERROR(AVERAGE(C23:I23),0) -> 0.2161678 | L23: =IFERROR(MEDIAN(C23:I23),0) -> 0.20340641
B24: Self Sust Growth Rate | C24: =IFERROR(C22*C23,0) -> 0.13093081 | D24: =IFERROR(D22*D23,0) -> 0.13965622 | E24: =IFERROR(E22*E23,0) -> 0.18627382 | F24: =IFERROR(F22*F23,0) -> 0.27212102 | G24: =IFERROR(G22*G23,0) -> 0.31175128 | H24: =IFERROR(H22*H23,0) -> 0.20340641 | I24: =IFERROR(I22*I23,0) -> 0.27301982 | K24: =IFERROR(AVERAGE(C24:I24),0) -> 0.21673705 | L24: =IFERROR(MEDIAN(C24:I24),0) -> 0.20340641
B25: Interest Cov Ratio | C25: =IFERROR((HistoricalFS!C18-HistoricalFS!C26)/HistoricalFS!C23,0) -> 1.9471967 | D25: =IFERROR((HistoricalFS!D18-HistoricalFS!D26)/HistoricalFS!D23,0) -> 1.8166235 | E25: =IFERROR((HistoricalFS!E18-HistoricalFS!E26)/HistoricalFS!E23,0) -> 1.5332681 | F25: =IFERROR((HistoricalFS!F18-HistoricalFS!F26)/HistoricalFS!F23,0) -> 8.1643369 | G25: =IFERROR((HistoricalFS!G18-HistoricalFS!G26)/HistoricalFS!G23,0) -> 9.2746766 | H25: =IFERROR((HistoricalFS!H18-HistoricalFS!H26)/HistoricalFS!H23,0) -> 15.2488 | I25: =IFERROR((HistoricalFS!I18-HistoricalFS!I26)/HistoricalFS!I23,0) -> 17.536257 | K25: =IFERROR(AVERAGE(C25:I25),0) -> 7.9315941 | L25: =IFERROR(MEDIAN(C25:I25),0) -> 8.1643369
B27: Debt Turnover Ratio | C27: =IFERROR(HistoricalFS!C6/HistoricalFS!C65,0) -> 14.231175 | D27: =IFERROR(HistoricalFS!D6/HistoricalFS!D65,0) -> 16.730466 | E27: =IFERROR(HistoricalFS!E6/HistoricalFS!E65,0) -> 30.850303 | F27: =IFERROR(HistoricalFS!F6/HistoricalFS!F65,0) -> 21.595182 | G27: =IFERROR(HistoricalFS!G6/HistoricalFS!G65,0) -> 11.7333 | H27: =IFERROR(HistoricalFS!H6/HistoricalFS!H65,0) -> 12.191818 | I27: =IFERROR(HistoricalFS!I6/HistoricalFS!I65,0) -> 10.647417 | K27: =IFERROR(AVERAGE(C27:I27),0) -> 16.854237 | L27: =IFERROR(MEDIAN(C27:I27),0) -> 14.231175
B28: Creditor Turnover Ratio | C28: =IFERROR(HistoricalFS!C6/HistoricalFS!C56,0) -> 4.1305104 | D28: =IFERROR(HistoricalFS!D6/HistoricalFS!D56,0) -> 3.2784568 | E28: =IFERROR(HistoricalFS!E6/HistoricalFS!E56,0) -> 2.0948924 | F28: =IFERROR(HistoricalFS!F6/HistoricalFS!F56,0) -> 1.2866226 | G28: =IFERROR(HistoricalFS!G6/HistoricalFS!G56,0) -> 1.7176871 | H28: =IFERROR(HistoricalFS!H6/HistoricalFS!H56,0) -> 1.5999934 | I28: =IFERROR(HistoricalFS!I6/HistoricalFS!I56,0) -> 2.1288325 | K28: =IFERROR(AVERAGE(C28:I28),0) -> 2.3195707 | L28: =IFERROR(MEDIAN(C28:I28),0) -> 2.0948924
B29: Invt Turnover | C29: =HistoricalFS!C6/HistoricalFS!C66 -> 8.2093702 | D29: =HistoricalFS!D6/HistoricalFS!D66 -> 5.3064674 | E29: =HistoricalFS!E6/HistoricalFS!E66 -> 5.3036587 | F29: =HistoricalFS!F6/HistoricalFS!F66 -> 2.4921351 | G29: =HistoricalFS!G6/HistoricalFS!G66 -> 4.4082296 | H29: =HistoricalFS!H6/HistoricalFS!H66 -> 5.365494 | I29: =HistoricalFS!I6/HistoricalFS!I66 -> 4.5318309 | K29: =IFERROR(AVERAGE(C29:I29),0) -> 5.0881694 | L29: =IFERROR(MEDIAN(C29:I29),0) -> 5.3036587
B30: Fixed Asset Turnover | C30: =IFERROR(HistoricalFS!C6/HistoricalFS!C59,0) -> 13.151763 | D30: =IFERROR(HistoricalFS!D6/HistoricalFS!D59,0) -> 6.8588388 | E30: =IFERROR(HistoricalFS!E6/HistoricalFS!E59,0) -> 4.5696103 | F30: =IFERROR(HistoricalFS!F6/HistoricalFS!F59,0) -> 6.1078922 | G30: =IFERROR(HistoricalFS!G6/HistoricalFS!G59,0) -> 7.8612339 | H30: =IFERROR(HistoricalFS!H6/HistoricalFS!H59,0) -> 3.5657068 | I30: =IFERROR(HistoricalFS!I6/HistoricalFS!I59,0) -> 3.6210025 | K30: =IFERROR(AVERAGE(C30:I30),0) -> 6.533721 | L30: =IFERROR(MEDIAN(C30:I30),0) -> 6.1078922
B31: Capital Turnover Ratio | C31: =IFERROR(HistoricalFS!C6/SUM(HistoricalFS!C53:C54),0) -> 6.6967989 | D31: =IFERROR(HistoricalFS!D6/SUM(HistoricalFS!D53:D54),0) -> 5.660396 | E31: =IFERROR(HistoricalFS!E6/SUM(HistoricalFS!E53:E54),0) -> 6.6743131 | F31: =IFERROR(HistoricalFS!F6/SUM(HistoricalFS!F53:F54),0) -> 3.6721243 | G31: =IFERROR(HistoricalFS!G6/SUM(HistoricalFS!G53:G54),0) -> 2.7881947 | H31: =IFERROR(HistoricalFS!H6/SUM(HistoricalFS!H53:H54),0) -> 1.52381 | I31: =IFERROR(HistoricalFS!I6/SUM(HistoricalFS!I53:I54),0) -> 1.838065 | K31: =IFERROR(AVERAGE(C31:I31),0) -> 4.1219574 | L31: =IFERROR(MEDIAN(C31:I31),0) -> 3.6721243
B33: (in days)
B34: Debtor Days | C34: =IFERROR(365/C27,0) -> 25.647917 | D34: =IFERROR(365/D27,0) -> 21.816487 | E34: =IFERROR(365/E27,0) -> 11.831326 | F34: =IFERROR(365/F27,0) -> 16.901918 | G34: =IFERROR(365/G27,0) -> 31.108044 | H34: =IFERROR(365/H27,0) -> 29.938111 | I34: =IFERROR(365/I27,0) -> 34.280615 | K34: =IFERROR(AVERAGE(C34:I34),0) -> 24.503488 | L34: =IFERROR(MEDIAN(C34:I34),0) -> 25.647917
B35: Payable Days | C35: =IFERROR(365/C28,0) -> 88.366804 | D35: =IFERROR(365/D28,0) -> 111.33287 | E35: =IFERROR(365/E28,0) -> 174.23329 | F35: =IFERROR(365/F28,0) -> 283.68848 | G35: =IFERROR(365/G28,0) -> 212.49504 | H35: =IFERROR(365/H28,0) -> 228.12595 | I35: =IFERROR(365/I28,0) -> 171.45548 | K35: =IFERROR(AVERAGE(C35:I35),0) -> 181.38542 | L35: =IFERROR(MEDIAN(C35:I35),0) -> 174.23329
B36: Invt Days | C36: =IFERROR(365/C29,0) -> 44.461389 | D36: =IFERROR(365/D29,0) -> 68.78399 | E36: =IFERROR(365/E29,0) -> 68.820416 | F36: =IFERROR(365/F29,0) -> 146.46076 | G36: =IFERROR(365/G29,0) -> 82.799679 | H36: =IFERROR(365/H29,0) -> 68.027287 | I36: =IFERROR(365/I29,0) -> 80.5414 | K36: =IFERROR(AVERAGE(C36:I36),0) -> 79.984989 | L36: =IFERROR(MEDIAN(C36:I36),0) -> 68.820416
B37: Cash Conversion Cycle | C37: =SUM(C34,C36-C35) -> -18.257498 | D37: =SUM(D34,D36-D35) -> -20.732392 | E37: =SUM(E34,E36-E35) -> -93.581546 | F37: =SUM(F34,F36-F35) -> -120.3258 | G37: =SUM(G34,G36-G35) -> -98.587318 | H37: =SUM(H34,H36-H35) -> -130.16055 | I37: =SUM(I34,I36-I35) -> -56.633466 | K37: =IFERROR(AVERAGE(C37:I37),0) -> -76.896939 | L37: =IFERROR(MEDIAN(C37:I37),0) -> -93.581546
B39: CFO/Sales | C39: =IFERROR(HistoricalFS!C112/HistoricalFS!C6,0) -> 0.041708004 | D39: =IFERROR(HistoricalFS!D112/HistoricalFS!D6,0) -> 0.034453446 | E39: =IFERROR(HistoricalFS!E112/HistoricalFS!E6,0) -> 0.24453188 | F39: =IFERROR(HistoricalFS!F112/HistoricalFS!F6,0) -> 0.2311154 | G39: =IFERROR(HistoricalFS!G112/HistoricalFS!G6,0) -> 0.20223889 | H39: =IFERROR(HistoricalFS!H112/HistoricalFS!H6,0) -> 0.21864447 | I39: =IFERROR(HistoricalFS!I112/HistoricalFS!I6,0) -> 0.06130927 | K39: =IFERROR(AVERAGE(C39:I39),0) -> 0.14771448 | L39: =IFERROR(MEDIAN(C39:I39),0) -> 0.20223889
B40: CFO/Total Assets | C40: =IFERROR(HistoricalFS!C112/HistoricalFS!C70,0) -> 0.088716468 | D40: =IFERROR(HistoricalFS!D112/HistoricalFS!D70,0) -> 0.052540745 | E40: =IFERROR(HistoricalFS!E112/HistoricalFS!E70,0) -> 0.32409742 | F40: =IFERROR(HistoricalFS!F112/HistoricalFS!F70,0) -> 0.21068103 | G40: =IFERROR(HistoricalFS!G112/HistoricalFS!G70,0) -> 0.20440841 | H40: =IFERROR(HistoricalFS!H112/HistoricalFS!H70,0) -> 0.16026609 | I40: =IFERROR(HistoricalFS!I112/HistoricalFS!I70,0) -> 0.054023909 | K40: =IFERROR(AVERAGE(C40:I40),0) -> 0.15639058 | L40: =IFERROR(MEDIAN(C40:I40),0) -> 0.16026609
B41: CFO/Total Debt | C41: =IFERROR(HistoricalFS!C112/HistoricalFS!C55,0) -> 0.5299548 | D41: =IFERROR(HistoricalFS!D112/HistoricalFS!D55,0) -> 0.19794057 | E41: =IFERROR(HistoricalFS!E112/HistoricalFS!E55,0) -> 1.9205856 | F41: =IFERROR(HistoricalFS!F112/HistoricalFS!F55,0) -> 4.8716083 | G41: =IFERROR(HistoricalFS!G112/HistoricalFS!G55,0) -> 4.1653084 | H41: =IFERROR(HistoricalFS!H112/HistoricalFS!H55,0) -> 2.6340587 | I41: =IFERROR(HistoricalFS!I112/HistoricalFS!I55,0) -> 0.50642466 | K41: =IFERROR(AVERAGE(C41:I41),0) -> 2.117983 | L41: =IFERROR(MEDIAN(C41:I41),0) -> 1.9205856

Sheet CashFlow Data
C2: 43891 | D2: 44256 | E2: 44621 | F2: 44986 | G2: 45352 | H2: 45717 | I2: 46082
B3: Cash from Operating Activity - | C3: 83 | D3: 67 | E3: 698 | F3: 1560 | G3: 2305 | H3: 3158 | I3: 1627
B4: Profit from operations | C4: 118 | D4: 107 | E4: 191 | F4: 941 | G4: 2049 | H4: 2744 | I4: 5916
B5: Receivables | C5: 86 | D5: 22 | E5: 21 | F5: -215 | G5: -670 | H5: -223 | I5: -1425
B6: Inventory | C6: -143 | D6: -99 | E6: -170 | F6: -2171 | G6: 123 | H6: -107 | I6: -3164
B7: Payables | C7: -12 | D7: 78 | E7: 178 | F7: 1073 | G7: -6 | H7: 557 | I7: 1014
B8: Operating Deposits | C8: 0 | D8: -3 | E8: 0 | F8: 0 | G8: 0 | H8: 0 | I8: -41
B9: Other WC items | C9: 46 | D9: -17 | E9: 504 | F9: 2032 | G9: 1144 | H9: 930 | I9: 476
B10: Working capital changes | C10: -23 | D10: -18 | E10: 533 | F10: 720 | G10: 592 | H10: 1157 | I10: -3140
B11: Direct taxes | C11: -11 | D11: -22 | E11: -26 | F11: -100 | G11: -335 | H11: -743 | I11: -1149
B12: Cash from Investing Activity - | C12: -22 | D12: -250 | E12: -673 | F12: -2088 | G12: -3346 | H12: -6806 | I12: -3953
B13: Fixed assets purchased | C13: -16 | D13: -70 | E13: -496 | F13: -865 | G13: -1342 | H13: -3274 | I13: -4882
B14: Fixed assets sold | C14: 0 | D14: 0 | E14: 1 | F14: 4 | G14: 5 | H14: 1 | I14: 46
... B32: CFO/OP | C32: 1.02 | D32: 1.05 | E32: 6.83 | F32: 1.99 | G32: 1.68 | H32: 1.43 | I32: 0.47

Sheet Data Sheet
A1: COMPANY NAME | B1: WAAREE ENERGIES LTD | E1: WAAREE ENERGIES LTD
A2: LATEST VERSION | B2: 2.1 | E2: PLEASE DO NOT MAKE ANY CHANGES TO THIS SHEET
A3: CURRENT VERSION | B3: 2.1
A5: META
A6: Number of shares | B6: =IF(B9>0, B9/B8, 0) -> 28.765138
A7: Face Value | B7: 10
A8: Current Price | B8: 2994.4
A9: Market Capitalization | B9: 86134.33
A15: PROFIT & LOSS
A16: Report Date | B16: 42825 | C16: 43190 | D16: 43555 | E16: 43921 | F16: 44286 | G16: 44651 | H16: 45016 | I16: 45382 | J16: 45747 | K16: 46112
A17: Sales | E17: 1995.78 | F17: 1952.78 | G17: 2854.27 | H17: 6750.87 | I17: 11397.61 | J17: 14444.5 | K17: 26536.77
A18: Raw Material Cost | E18: 1649.24 | F18: 1684.54 | G18: 2258.1 | H18: 6157.99 | I18: 9321.79 | J18: 9537.03 | K18: 20035.91
A19: Change in Inventory | E19: 19.51 | F19: 73.08 | G19: -63.6 | H19: 1006.9 | I19: 561.99 | J19: -652.79 | K19: 1954.97
A20: Power and Fuel | E20: 12.65 | F20: 10.11 | G20: 19.71 | H20: 50.51 | I20: 88.39 | J20: 115.61
A21: Other Mfr. Exp | E21: 133.67 | F21: 137.6 | G21: 267.74 | H21: 412.53 | I21: 167.26 | J21: 219.48
A22: Employee Cost | E22: 55.43 | F22: 49.38 | G22: 56.91 | H22: 123.79 | I22: 177.15 | J22: 318.17 | K22: 599.25
A23: Selling and admin | E23: 49.04 | F23: 44.78 | G23: 56.23 | H23: 121.18 | I23: 574.71 | J23: 738.77 | K23: 1947.94
A24: Other Expenses | E24: 22.49 | F24: 14.62 | G24: 26.03 | H24: 55.96 | I24: 55.87 | J24: 141.01
A25: Other Income | E25: 25.01 | F25: 44.65 | G25: 96.58 | H25: 87.74 | I25: 576.49 | J25: 397.54 | K25: 413.37
A26: Depreciation | E26: 27.13 | F26: 28.66 | G26: 43.27 | H26: 164.13 | I26: 276.81 | J26: 402.45 | K26: 989.72
A27: Interest | E27: 33.71 | F27: 30.92 | G27: 40.88 | H27: 82.27 | I27: 139.91 | J27: 152.09 | K27: 280.5
A28: Profit before tax | E28: 56.94 | F28: 69.9 | G28: 118.38 | H28: 677.15 | I28: 1734.2 | J28: 2564.64 | K28: 5051.79
A29: Tax | E29: 17.92 | F29: 21.72 | G29: 38.72 | H29: 176.88 | I29: 459.82 | J29: 636.51 | K29: 1167.64
A30: Net profit | E30: 41.71 | F30: 49.21 | G30: 75.64 | H30: 482.76 | I30: 1237.18 | J30: 1867.39 | K30: 3711.3
A31: Dividend Amount | K31: 57.53
A40: Quarters
A41: Report Date | B41: 45291 | C41: 45382 | D41: 45473 | E41: 45565 | F41: 45657 | G41: 45747 | H41: 45838 | I41: 45930 | J41: 46022 | K41: 46112
A42: Sales | B42: 1596.18 | C42: 2935.84 | D42: 3408.9 | E42: 3574.38 | F42: 3457.29 | G42: 4003.93 | H42: 4425.83 | I42: 6065.64 | J42: 7565.05 | K42: 8480.25
A43: Expenses | B43: 1424.95 | C43: 2517.5 | D43: 2856.42 | E43: 3049.53 | F43: 2735.56 | G43: 3081.35 | H43: 3428.51 | I43: 4659.24 | J43: 5636.89 | K43: 6903.5
A44: Other Income | B44: 104.7 | C44: 363.83 | D44: 87.51 | E44: 89.09 | F44: 87.98 | G44: 132.97 | H44: 171.35 | I44: 160.9 | J44: -98.6 | K44: 179.73
A45: Depreciation | B45: 73.9 | C45: 75.15 | D45: 75.77 | E45: 84.27 | F45: 89.05 | G45: 153.38 | H45: 182.06 | I45: 239.76 | J45: 267.26 | K45: 300.64
A46: Interest | B46: 18.45 | C46: 48.41 | D46: 33.7 | E46: 30.83 | F46: 30.85 | G46: 56.72 | H46: 43.25 | I46: 96.08 | J46: 93.28 | K46: 47.89
A47: Profit before tax | B47: 183.58 | C47: 658.61 | D47: 530.52 | E47: 498.84 | F47: 689.81 | G47: 845.45 | H47: 943.36 | I47: 1231.46 | J47: 1469.02 | K47: 1407.95
A48: Tax | B48: 42.77 | C48: 183.45 | D48: 129.41 | E48: 123.18 | F48: 182.93 | G48: 200.99 | H48: 170.47 | I48: 353.25 | J48: 362.23 | K48: 281.69
A49: Net profit | B49: 124.53 | C49: 461.52 | D49: 394.14 | E49: 361.65 | F49: 492.69 | G49: 618.91 | H49: 745.2 | I49: 842.55 | J49: 1062.46 | K49: 1061.1
A50: Operating Profit | B50: 171.23 | C50: 418.34 | D50: 552.48 | E50: 524.85 | F50: 721.73 | G50: 922.58 | H50: 997.32 | I50: 1406.4 | J50: 1928.16 | K50: 1576.75
A55: BALANCE SHEET
A56: Report Date | B56: 42825 | C56: 43190 | D56: 43555 | E56: 43921 | F56: 44286 | G56: 44651 | H56: 45016 | I56: 45382 | J56: 45747 | K56: 46112
A57: Equity Share Capital | E57: 197.14 | F57: 197.14 | G57: 197.14 | H57: 243.37 | I57: 262.96 | J57: 287.28 | K57: 287.65
A58: Reserves | E58: 100.88 | F58: 147.85 | G58: 230.51 | H58: 1595.04 | I58: 3824.85 | J58: 9191.92 | K58: 14149.69
...

Sheet Forecast
B1: Tata Motors
B2: Year Weight | C2: Year | D2: Sales | E2: Sales Growth
B3: 1 | C3: 2015 | D3: 263159
B4: =B3+1 -> 2 | C4: =C3+1 -> 2016 | D4: 273046 | E4: =D4/D3-1 -> 0.037570442
B5: =B4+1 -> 3 | C5: =C4+1 -> 2017 | D5: 269693 | E5: =D5/D4-1 -> -0.012279982
B6: =B5+1 -> 4 | C6: =C5+1 -> 2018 | D6: 291550 | E6: =D6/D5-1 -> 0.081044002
B7: =B6+1 -> 5 | C7: =C6+1 -> 2019 | D7: 301938 | E7: =D7/D6-1 -> 0.035630252
B8: =B7+1 -> 6 | C8: =C7+1 -> 2020 | D8: 261068 | E8: =D8/D7-1 -> -0.13535891
B9: =B8+1 -> 7 | C9: =C8+1 -> 2021 | D9: 249795 | E9: =D9/D8-1 -> -0.043180321
B10: =B9+1 -> 8 | C10: =C9+1 -> 2022 | D10: 278454 | E10: =D10/D9-1 -> 0.11473008 | G10: SUMMARY OUTPUT
B11: =B10+1 -> 9 | C11: =C10+1 -> 2023 | D11: 345967 | E11: =D11/D10-1 -> 0.24245656
B12: =B11+1 -> 10 | C12: =C11+1 -> 2024 | D12: 434016 | E12: =D12/D11-1 -> 0.25450115 | G12: Regression Statistics
B13: =B12+1 -> 11 | C13: =C12+1 -> 2025 | D13: 439695 | E13: =D13/D12-1 -> 0.013084771 | G13: Multiple R | H13: 0.70368468
B14: =B13+1 -> 12 | C14: =C13+1 -> 2026 | D14: 335582 | E14: =D14/D13-1 -> -0.23678459 | G14: R Square | H14: 0.49517212 | I14: Strength of regr should be more than 0.4
B15: =B14+1 -> 13 | C15: =C14+1 -> 2027 | D15: =FORECAST(B15,$D$3:$D$14,$B$3:$B$14) -> 394658.62 | E15: =D15/D14-1 -> 0.17604228 | G15: Adjusted R Square | H15: 0.44468934
B16: =B15+1 -> 14 | C16: =C15+1 -> 2028 | D16: =FORECAST(B16,$D$3:$D$14,$B$3:$B$14) -> 407375.81 | E16: =D16/D15-1 -> 0.032223255 | G16: Standard Error | H16: 48557.083
B17: =B16+1 -> 15 | C17: =C16+1 -> 2029 | D17: =FORECAST(B17,$D$3:$D$14,$B$3:$B$14) -> 420092.99 | E17: =D17/D16-1 -> 0.031217331 | G17: Observations | H17: 12
B18: =B17+1 -> 16 | C18: =C17+1 -> 2030 | D18: =FORECAST(B18,$D$3:$D$14,$B$3:$B$14) -> 432810.18 | E18: =D18/D17-1 -> 0.03027231
B19: =B18+1 -> 17 | C19: =C18+1 -> 2031 | D19: =FORECAST(B19,$D$3:$D$14,$B$3:$B$14) -> 445527.36 | E19: =D19/D18-1 -> 0.029382824 | G19: ANOVA
H20: df | I20: SS | J20: MS | K20: F | L20: Significance F
G21: Regression | H21: 1 | I21: 2.3126933e+10 | J21: 2.3126933e+10 | K21: 9.8087318 | L21: 0.01065618
B22: 13 | C22: 2027 | D22: 394658.62 | E22: 0.17604228 | G22: Residual | H22: 10 | I22: 2.3577903e+10 | J22: 2.3577903e+09
B23: 14 | C23: 2028 | D23: 407375.81 | E23: 0.032223255 | G23: Total | H23: 11 | I23: 4.6704836e+10
B24: 15 | C24: 2029 | D24: 420092.99 | E24: 0.031217331
B25: 16 | C25: 2030 | D25: 432810.18 | E25: 0.03027231 | H25: Coefficients | I25: Standard Error | J25: t Stat | K25: P-value | L25: Lower 95% | M25: Upper 95% | N25: Lower 95.0% | O25: Upper 95.0%
B26: 17 | C26: 2031 | D26: 445527.36 | E26: 0.029382824 | G26: Intercept | H26: 229335.21 | I26: 29884.819 | J26: 7.6739703 | K26: 1.6920326e-05 | L26: 162747.69 | M26: 295922.74 | N26: 162747.69 | O26: 295922.74
G27: Year Weight | H27: 12717.185 | I27: 4060.5473 | J27: 3.1318895 | K27: 0.01065618 | L27: 3669.7222 | M27: 21764.648 | N27: 3669.7222 | O27: 21764.648

Sheet Sheet2
B2: ='Data Sheet'!$B$1&" - "&'Data Sheet'!$A$17&" Forecasting" -> WAAREE ENERGIES LTD - Sales Forecasting | G2: ='Data Sheet'!$B$1&" - "&HistoricalFS!B18&" Forecasting" -> WAAREE ENERGIES LTD - EBITDA Forecasting | L2: ='Data Sheet'!$B$1&" - "&HistoricalFS!B43&" Forecasting" -> WAAREE ENERGIES LTD - EPS Forecasting
B3: Year Weight | C3: Year | D3: Sales | E3: Sales Growth | G3: Year Weight | H3: Year | I3: EBITDA | J3: EBITDA Growth | L3: Year Weight | M3: Year | N3: EPS | O3: EPS Growth
B4: 1 | C4: ='Data Sheet'!$B$16 -> 42825 | D4: {=TRANSPOSE('Data Sheet'!B17:K17)} -> 0 | G4: 1 | H4: ='Data Sheet'!$B$16 -> 42825 | I4: {=TRANSPOSE(HistoricalFS!C18:I18)} -> 92.77 | L4: 1 | M4: ='Data Sheet'!$B$16 -> 42825 | N4: {=TRANSPOSE(HistoricalFS!C43:I43)} -> 1.9797057
B5: =B4+1 -> 2 | C5: =C4+365 -> 43190 | D5: 0 | E5: =D5/D4-1 -> #DIV/0! | G5: =G4+1 -> 2 | H5: =H4+365 -> 43190 | I5: 84.83 | J5: =I5/I4-1 -> -0.085588013 | L5: =L4+1 -> 2 | M5: =M4+365 -> 43190 | N5: 2.4444444 | O5: =N5/N4-1 -> 0.23475141
B6: =B5+1 -> 3 | C6: =C5+365 -> 43555 | D6: 0 | E6: =D6/D5-1 -> #DIV/0! | G6: =G5+1 -> 3 | H6: =H5+365 -> 43555 | I6: 105.95 | J6: =I6/I5-1 -> 0.24896853 | L6: =L5+1 -> 3 | M6: =M5+365 -> 43555 | N6: 4.0416032 | O6: =N6/N5-1 -> 0.65338315
B7: =B6+1 -> 4 | C7: =C6+365 -> 43920 | D7: 1995.78 | E7: =D7/D6-1 -> #DIV/0! | G7: =G6+1 -> 4 | H7: =H6+365 -> 43920 | I7: 835.81 | J7: =I7/I6-1 -> 6.8887211 | L7: =L6+1 -> 4 | M7: =M6+365 -> 43920 | N7: 25.381532 | O7: =N7/N6-1 -> 5.2800653
B8: =B7+1 -> 5 | C8: =C7+365 -> 44285 | D8: 1952.78 | E8: =D8/D7-1 -> -0.021545461 | G8: =G7+1 -> 5 | H8: =H7+365 -> 44285 | I8: 1574.43 | J8: =I8/I7-1 -> 0.88371759 | L8: =L7+1 -> 5 | M8: =M7+365 -> 44285 | N8: 64.65652 | O8: =N8/N7-1 -> 1.5473844
B9: =B8+1 -> 6 | C9: =C8+365 -> 44650 | D9: 2854.27 | E9: =D9/D8-1 -> 0.46164442 | G9: =G8+1 -> 6 | H9: =H8+365 -> 44650 | I9: 2721.64 | J9: =I9/I8-1 -> 0.728651 | L9: =L8+1 -> 6 | M9: =M8+365 -> 44650 | N9: 67.112078 | O9: =N9/N8-1 -> 0.037978512
B10: =B9+1 -> 7 | C10: =C9+365 -> 45015 | D10: 6750.87 | E10: =D10/D9-1 -> 1.3651827 | G10: =G9+1 -> 7 | H10: =H9+365 -> 45015 | I10: 5908.64 | J10: =I10/I9-1 -> 1.1709851 | L10: =L9+1 -> 7 | M10: =M9+365 -> 45015 | N10: 135.00695 | O10: =N10/N9-1 -> 1.011664
B11: =B10+1 -> 8 | C11: =C10+365 -> 45380 | D11: 11397.61 | E11: =D11/D10-1 -> 0.68831721 | G11: =G10+1 -> 8 | H11: =H10+365 -> 45380 | I11: #N/A | J11: =I11/I10-1 -> #N/A | L11: =L10+1 -> 8 | M11: =M10+365 -> 45380 | N11: #N/A | O11: =N11/N10-1 -> #N/A
B12: =B11+1 -> 9 | C12: =C11+365 -> 45745 | D12: 14444.5 | E12: =D12/D11-1 -> 0.2673271 | G12: =G11+1 -> 9 | H12: =H11+365 -> 45745 | I12: #N/A | J12: =I12/I11-1 -> #N/A | L12: =L11+1 -> 9 | M12: =M11+365 -> 45745 | N12: #N/A | O12: =N12/N11-1 -> #N/A
B13: =B12+1 -> 10 | C13: =C12+365 -> 46110 | D13: 26536.77 | E13: =D13/D12-1 -> 0.83715393 | G13: =G12+1 -> 10 | H13: =H12+365 -> 46110 | I13: #N/A | J13: =I13/I12-1 -> #N/A | L13: =L12+1 -> 10 | M13: =M12+365 -> 46110 | N13: #N/A | O13: =N13/N12-1 -> #N/A
B14: =B13+1 -> 11 | C14: =C13+365 -> 46475 | D14: =FORECAST(B14,$D$4:$D$13,$B$4:$B$13) -> 20329.833 | E14: =D14/D13-1 -> -0.2338995 | G14: =G13+1 -> 11 | H14: =H13+365 -> 46475 | I14: =FORECAST(G14,$I$4:$I$13,$G$4:$G$13) -> #N/A | J14: =I14/I13-1 -> #N/A | L14: =L13+1 -> 11 | M14: =M13+365 -> 46475 | N14: =FORECAST(L14,$N$4:$N$13,$L$4:$L$13) -> #N/A | O14: =N14/N13-1 -> #N/A
B15: =B14+1 -> 12 | C15: =C14+365 -> 46840 | D15: =FORECAST(B15,$D$4:$D$13,$B$4:$B$13) -> 22827.392 | E15: =D15/D14-1 -> 0.12285192 | G15: =G14+1 -> 12 | H15: =H14+365 -> 46840 | I15: =FORECAST(G15,$I$4:$I$13,$G$4:$G$13) -> #N/A | J15: =I15/I14-1 -> #N/A | L15: =L14+1 -> 12 | M15: =M14+365 -> 46840 | N15: =FORECAST(L15,$N$4:$N$13,$L$4:$L$13) -> #N/A | O15: =N15/N14-1 -> #N/A
B16: =B15+1 -> 13 | C16: =C15+365 -> 47205 | D16: =FORECAST(B16,$D$4:$D$13,$B$4:$B$13) -> 25324.951 | E16: =D16/D15-1 -> 0.10941062 | G16: =G15+1 -> 13 | H16: =H15+365 -> 47205 | I16: =FORECAST(G16,$I$4:$I$13,$G$4:$G$13) -> #N/A | J16: =I16/I15-1 -> #N/A | L16: =L15+1 -> 13 | M16: =M15+365 -> 47205 | N16: =FORECAST(L16,$N$4:$N$13,$L$4:$L$13) -> #N/A | O16: =N16/N15-1 -> #N/A
B17: =B16+1 -> 14 | C17: =C16+365 -> 47570 | D17: =FORECAST(B17,$D$4:$D$13,$B$4:$B$13) -> 27822.51 | E17: =D17/D16-1 -> 0.098620489 | G17: =G16+1 -> 14 | H17: =H16+365 -> 47570 | I17: =FORECAST(G17,$I$4:$I$13,$G$4:$G$13) -> #N/A | J17: =I17/I16-1 -> #N/A | L17: =L16+1 -> 14 | M17: =M16+365 -> 47570 | N17: =FORECAST(L17,$N$4:$N$13,$L$4:$L$13) -> #N/A | O17: =N17/N16-1 -> #N/A
B18: =B17+1 -> 15 | C18: =C17+365 -> 47935 | D18: =FORECAST(B18,$D$4:$D$13,$B$4:$B$13) -> 30320.069 | E18: =D18/D17-1 -> 0.089767568 | G18: =G17+1 -> 15 | H18: =H17+365 -> 47935 | I18: =FORECAST(G18,$I$4:$I$13,$G$4:$G$13) -> #N/A | J18: =I18/I17-1 -> #N/A | L18: =L17+1 -> 15 | M18: =M17+365 -> 47935 | N18: =FORECAST(L18,$N$4:$N$13,$L$4:$L$13) -> #N/A | O18: =N18/N17-1 -> #N/A
